Workbook

Sheet 00_はじめに
A1: AIセキュリティロードマップ作成ツール（AIMF v0.1 β版：AIセキュリティ＆ガバナンス統合マスターフレームワーク準拠）
A2: 207問評価（6区分×37カテゴリ）→ 適用自動判定 → 施策抽出 → 優先順位付け → ロードマップ → ガントチャート → ダッシュボードまでを自動生成します。
A3: 評価質問と施策はAIMF v0.1（β版）の207コントロール（19基準対応：NIST CSF 2.0 / AI RMF / ISO 42001 / OWASP AISVS・LLM10・ASI10 / EU AI Act / MITRE ATLAS / ASDエージェントAIガイダンス / Five Eyes声明 ほか）から生成。
A6: ■ 使い方（基本フロー）
A7: ステップ | B7: シート | C7: 内容
A8: Step0 | B8: 00_はじめに | C8: AI利用プロファイル（下表）を設定。利用しないAI類型の質問は自動で「対象外」になります。
A9: Step1 | B9: 01_評価入力 | C9: 現状評価（黄色セル）を入力。影響度〜導入難易度は初期値入り（青字）で、必要に応じて調整可。
A10: Step2 | B10: 自動計算 | C10: 適用判定・ギャップ・優先度スコア・抽出対象が自動判定されます。
A11: Step3 | B11: 05/06 | C11: 抽出施策と推奨優先度が自動生成されます（閲覧のみ）。
A12: Step4 | B12: 07_短中長Top5 | C12: 短期・中期・長期それぞれの優先施策Top5を自動表示。
A13: Step5 | B13: 08_ロードマップ | C13: 区分別の実行計画一覧を自動生成。
A14: Step6 | B14: 09/10_ガント | C14: 依存関係を考慮した開始・終了月とガントチャート（36か月）を自動描画。
A15: Step7 | B15: 11_ダッシュボード | C15: 区分別レーダー・control-type別・AI類型別レディネスを確認し、12_PPT出力データを報告書へ転記。
A17: ■ 設定（必要に応じて変更可・黄色セル）
A18: 設定項目 | B18: 値 | C18: 説明
A19: 優先度スコア閾値 | B19: 40 | C19: 現状<目標でなくてもスコアがこの値以上なら施策を抽出
A20: 短期 開始月 | B20: 1 | C20: 短期施策の標準開始月（プロジェクト開始からの月数）
A21: 中期 開始月 | B21: 7 | C21: 中期施策の標準開始月
A22: 長期 開始月 | B22: 19 | C22: 長期施策の標準開始月
A23: ■ AI利用プロファイル（Y/N・黄色セル） | C23: 利用しない類型に固有の質問は自動で「対象外」となり、集計の分母から除外されます。
A24: 従来型AI（判別・分類モデル等）の利用 | B24: Y | C24: ai-scopeにtraditional-aiを含む質問の適用判定に使用
A25: 生成AI（LLM・RAG）の利用 | B25: Y | C25: ai-scopeにgenerative-aiを含む質問の適用判定に使用
A26: AIエージェント（単体）の利用 | B26: Y | C26: ai-scopeにai-agentを含む質問の適用判定に使用
A27: マルチエージェントの利用 | B27: Y | C27: ai-scopeにmulti-agentを含む質問の適用判定に使用
A29: ■ 評価基準・凡例
A30: 現状評価/目標評価 (0-4) | B30: 0=未実施 / 1=一部実施 / 2=限定運用 / 3=標準運用 / 4=高度運用・最適化 | C30: 入力例: 現状=2（限定運用）
A31: 優先度スコア | B31: ギャップ×影響度×発生可能性×ビジネス重要度×QuickWin×依存係数 ÷ 導入難易度 | C31: 影響度〜導入難易度(1-5)は施策属性から導出した初期値入り（青字）。ヒアリング結果に応じて調整可
A32: control-type | B32: AI-Expansion=AI特有の新設管理策 / AI-Enhancement=既存セキュリティ管理策のAI拡張 | C32: ダッシュボードで「AI固有統制の未整備」と「既存運用の適用漏れ」を分けて把握
A33: 目標評価の初期値 | B33: ベースライン(baseline)=4 / 拡張(extended)=3 | C33: 段階適用の考え方に基づく初期値。組織の方針に応じて調整可
A34: セルの色 | B34: 黄色=入力セル / 青字=調整可能な初期値 / 白=自動計算（編集不可）

Sheet 01_評価入力
A1: 質問ID | B1: 区分 | C1: カテゴリ | D1: コントロール名 | E1: 質問 | F1: Type | G1: ai-scope | H1: 適用 | I1: 現状評価 (0-4) | J1: 目標評価 (0-4) | K1: ギャップ | L1: 影響度 (1-5) | M1: 発生可能性 (1-5) | N1: ビジネス 重要度(1-5) | O1: QuickWin (1-5) | P1: 依存係数 (1-5) | Q1: 導入難易度 (1-5) | R1: 優先度 スコア | S1: 抽出対象 | T1: 推奨施策ID | U1: 推奨施策名 | V1: 調整スコア (内部) | W1: スコア順位 (内部) | X1: lineage (内部)
A2: AIMF-GV-ORG-001 | B2: GV | C2: ORG | D2: AIガバナンス委員会の設置 | E2: 経営層、CISO、法務、IT部門、事業部門の代表からなるクロスファンクショナルな統治組織を組成し、責任の所在を明確にしていますか。 | F2: AI-Enhancement | G2: all | H2: =IF(OR($G2="all",AND(00_はじめに!$B$24="Y",ISNUMBER(SEARCH("traditional",$G2))),AND(00_はじめに!$B$25="Y",ISNUMBER(SEARCH("generative",$G2))),AND(00_はじめに!$B$26="Y",ISNUMBER(SEARCH("ai-agent",$G2))),AND(00_はじめに!$B$27="Y",ISNUMBER(SEARCH("multi-agent",$G2)))),"○","対象外") -> ○ | J2: 4 | K2: =IF(OR($H2="対象外",$I2="",$J2=""),"",$J2-$I2) | L2: 4 | M2: 3 | N2: 5 | O2: 5 | P2: 4 | Q2: 2 | R2: =IF(OR($H2="対象外",$K2="",$L2="",$M2="",$N2="",$O2="",$P2="",$Q2=""),"",($K2*$L2*$M2*$N2*$O2*$P2)/$Q2) | S2: =IF($H2="対象外","",IF(OR($I2="",$J2=""),"",IF(OR($J2-$I2>0,AND($R2<>"",$R2>=00_はじめに!$B$19)),"○",""))) | T2: =IFERROR(VLOOKUP($A2,03_質問施策マッピング!$A:$B,2,0),"") -> AIMF-GV-ORG-001 | U2: =IF($T2="","",IFERROR(VLOOKUP($T2,02_施策マスター!$A:$B,2,0),"")) -> AIガバナンス委員会の設置 | V2: =IF($R2="","",$R2+(1000-ROW())/1000000) | W2: =IF($V2="","",COUNTIF($V$2:$V$208,">"&$V2)+1) | X2: baseline
A3: AIMF-GV-ORG-002 | B3: GV | C3: ORG | D3: AI活用基本方針・ガイドラインの策定 | E3: 全社的なAI利用の目的、許容リスクレベル、禁止事項（機密情報の公衆AIへの入力禁止等）を定義・規程化していますか。 | F3: AI-Enhancement | G3: all | H3: =IF(OR($G3="all",AND(00_はじめに!$B$24="Y",ISNUMBER(SEARCH("traditional",$G3))),AND(00_はじめに!$B$25="Y",ISNUMBER(SEARCH("generative",$G3))),AND(00_はじめに!$B$26="Y",ISNUMBER(SEARCH("ai-agent",$G3))),AND(00_はじめに!$B$27="Y",ISNUMBER(SEARCH("multi-agent",$G3)))),"○","対象外") -> ○ | J3: 4 | K3: =IF(OR($H3="対象外",$I3="",$J3=""),"",$J3-$I3) | L3: 4 | M3: 3 | N3: 5 | O3: 5 | P3: 4 | Q3: 2 | R3: =IF(OR($H3="対象外",$K3="",$L3="",$M3="",$N3="",$O3="",$P3="",$Q3=""),"",($K3*$L3*$M3*$N3*$O3*$P3)/$Q3) | S3: =IF($H3="対象外","",IF(OR($I3="",$J3=""),"",IF(OR($J3-$I3>0,AND($R3<>"",$R3>=00_はじめに!$B$19)),"○",""))) | T3: =IFERROR(VLOOKUP($A3,03_質問施策マッピング!$A:$B,2,0),"") -> AIMF-GV-ORG-002 | U3: =IF($T3="","",IFERROR(VLOOKUP($T3,02_施策マスター!$A:$B,2,0),"")) -> AI活用基本方針・ガイドラインの策定 | V3: =IF($R3="","",$R3+(1000-ROW())/1000000) | W3: =IF($V3="","",COUNTIF($V$2:$V$208,">"&$V3)+1) | X3: baseline
A4: AIMF-GV-ORG-003 | B4: GV | C4: ORG | D4: AIリスクアセスメント・プロジェクト承認プロセスの構築 | E4: 新規AIプロジェクト開始前に機密性・影響度に応じたセキュリティ審査を義務付け、継続的アセスメント体制へシフトしていますか。 | F4: AI-Enhancement | G4: all | H4: =IF(OR($G4="all",AND(00_はじめに!$B$24="Y",ISNUMBER(SEARCH("traditional",$G4))),AND(00_はじめに!$B$25="Y",ISNUMBER(SEARCH("generative",$G4))),AND(00_はじめに!$B$26="Y",ISNUMBER(SEARCH("ai-agent",$G4))),AND(00_はじめに!$B$27="Y",ISNUMBER(SEARCH("multi-agent",$G4)))),"○","対象外") -> ○ | J4: 4 | K4: =IF(OR($H4="対象外",$I4="",$J4=""),"",$J4-$I4) | L4: 4 | M4: 3 | N4: 5 | O4: 5 | P4: 4 | Q4: 2 | R4: =IF(OR($H4="対象外",$K4="",$L4="",$M4="",$N4="",$O4="",$P4="",$Q4=""),"",($K4*$L4*$M4*$N4*$O4*$P4)/$Q4) | S4: =IF($H4="対象外","",IF(OR($I4="",$J4=""),"",IF(OR($J4-$I4>0,AND($R4<>"",$R4>=00_はじめに!$B$19)),"○",""))) | T4: =IFERROR(VLOOKUP($A4,03_質問施策マッピング!$A:$B,2,0),"") -> AIMF-GV-ORG-003 | U4: =IF($T4="","",IFERROR(VLOOKUP($T4,02_施策マスター!$A:$B,2,0),"")) -> AIリスクアセスメント・プロジェクト承認プロセスの構築 | V4: =IF($R4="","",$R4+(1000-ROW())/1000000) | W4: =IF($V4="","",COUNTIF($V$2:$V$208,">"&$V4)+1) | X4: baseline
A5: AIMF-GV-ORG-004 | B5: GV | C5: ORG | D5: AIセキュリティ文化の醸成 | E5: 定期的な教育・啓発活動を通じ、全従業員がセキュリティを意識した行動をとれる文化を醸成していますか。 | F5: AI-Enhancement | G5: all | H5: =IF(OR($G5="all",AND(00_はじめに!$B$24="Y",ISNUMBER(SEARCH("traditional",$G5))),AND(00_はじめに!$B$25="Y",ISNUMBER(SEARCH("generative",$G5))),AND(00_はじめに!$B$26="Y",ISNUMBER(SEARCH("ai-agent",$G5))),AND(00_はじめに!$B$27="Y",ISNUMBER(SEARCH("multi-agent",$G5)))),"○","対象外") -> ○ | J5: 4 | K5: =IF(OR($H5="対象外",$I5="",$J5=""),"",$J5-$I5) | L5: 4 | M5: 3 | N5: 5 | O5: 5 | P5: 4 | Q5: 2 | R5: =IF(OR($H5="対象外",$K5="",$L5="",$M5="",$N5="",$O5="",$P5="",$Q5=""),"",($K5*$L5*$M5*$N5*$O5*$P5)/$Q5) | S5: =IF($H5="対象外","",IF(OR($I5="",$J5=""),"",IF(OR($J5-$I5>0,AND($R5<>"",$R5>=00_はじめに!$B$19)),"○",""))) | T5: =IFERROR(VLOOKUP($A5,03_質問施策マッピング!$A:$B,2,0),"") -> AIMF-GV-ORG-004 | U5: =IF($T5="","",IFERROR(VLOOKUP($T5,02_施策マスター!$A:$B,2,0),"")) -> AIセキュリティ文化の醸成 | V5: =IF($R5="","",$R5+(1000-ROW())/1000000) | W5: =IF($V5="","",COUNTIF($V$2:$V$208,">"&$V5)+1) | X5: baseline
A6: AIMF-GV-ORG-005 | B6: GV | C6: ORG | D6: AIセキュリティの社内コミュニケーション強化 | E6: AIセキュリティ情報・インシデントを迅速かつ透明に共有するコミュニケーションチャネルを確立していますか。 | F6: AI-Enhancement | G6: all | H6: =IF(OR($G6="all",AND(00_はじめに!$B$24="Y",ISNUMBER(SEARCH("traditional",$G6))),AND(00_はじめに!$B$25="Y",ISNUMBER(SEARCH("generative",$G6))),AND(00_はじめに!$B$26="Y",ISNUMBER(SEARCH("ai-agent",$G6))),AND(00_はじめに!$B$27="Y",ISNUMBER(SEARCH("multi-agent",$G6)))),"○","対象外") -> ○ | J6: 4 | K6: =IF(OR($H6="対象外",$I6="",$J6=""),"",$J6-$I6) | L6: 4 | M6: 3 | N6: 5 | O6: 5 | P6: 4 | Q6: 2 | R6: =IF(OR($H6="対象外",$K6="",$L6="",$M6="",$N6="",$O6="",$P6="",$Q6=""),"",($K6*$L6*$M6*$N6*$O6*$P6)/$Q6) | S6: =IF($H6="対象外","",IF(OR($I6="",$J6=""),"",IF(OR($J6-$I6>0,AND($R6<>"",$R6>=00_はじめに!$B$19)),"○",""))) | T6: =IFERROR(VLOOKUP($A6,03_質問施策マッピング!$A:$B,2,0),"") -> AIMF-GV-ORG-005 | U6: =IF($T6="","",IFERROR(VLOOKUP($T6,02_施策マスター!$A:$B,2,0),"")) -> AIセキュリティの社内コミュニケーション強化 | V6: =IF($R6="","",$R6+(1000-ROW())/1000000) | W6: =IF($V6="","",COUNTIF($V$2:$V$208,">"&$V6)+1) | X6: baseline
A7: AIMF-GV-ORG-006 | B7: GV | C7: ORG | D7: AI統括責任者（CAIO/AIセキュリティ責任者）の任命 | E7: AIのリスクとセキュリティに関する説明責任を負う役員級の責任者を任命し、取締役会への定期報告ラインを確立していますか。 | F7: AI-Enhancement | G7: all | H7: =IF(OR($G7="all",AND(00_はじめに!$B$24="Y",ISNUMBER(SEARCH("traditional",$G7))),AND(00_はじめに!$B$25="Y",ISNUMBER(SEARCH("generative",$G7))),AND(00_はじめに!$B$26="Y",ISNUMBER(SEARCH("ai-agent",$G7))),AND(00_はじめに!$B$27="Y",ISNUMBER(SEARCH("multi-agent",$G7)))),"○","対象外") -> ○ | J7: 3 | K7: =IF(OR($H7="対象外",$I7="",$J7=""),"",$J7-$I7) | L7: 4 | M7: 3 | N7: 5 | O7: 5 | P7: 4 | Q7: 2 | R7: =IF(OR($H7="対象外",$K7="",$L7="",$M7="",$N7="",$O7="",$P7="",$Q7=""),"",($K7*$L7*$M7*$N7*$O7*$P7)/$Q7) | S7: =IF($H7="対象外","",IF(OR($I7="",$J7=""),"",IF(OR($J7-$I7>0,AND($R7<>"",$R7>=00_はじめに!$B$19)),"○",""))) | T7: =IFERROR(VLOOKUP($A7,03_質問施策マッピング!$A:$B,2,0),"") -> AIMF-GV-ORG-006 | U7: =IF($T7="","",IFERROR(VLOOKUP($T7,02_施策マスター!$A:$B,2,0),"")) -> AI統括責任者（CAIO/AIセキュリティ責任者）の任命 | V7: =IF($R7="","",$R7+(1000-ROW())/1000000) | W7: =IF($V7="","",COUNTIF($V$2:$V$208,">"&$V7)+1) | X7: extended
A8: AIMF-GV-ORG-007 | B8: GV | C8: ORG | D8: AIセキュリティ予算・リソースの確保 | E8: AI脅威の進展速度に見合うセキュリティ投資（人員・ツール・訓練）を経営レベルで確保し、毎年見直していますか。 | F8: AI-Enhancement | G8: all | H8: =IF(OR($G8="all",AND(00_はじめに!$B$24="Y",ISNUMBER(SEARCH("traditional",$G8))),AND(00_はじめに!$B$25="Y",ISNUMBER(SEARCH("generative",$G8))),AND(00_はじめに!$B$26="Y",ISNUMBER(SEARCH("ai-agent",$G8))),AND(00_はじめに!$B$27="Y",ISNUMBER(SEARCH("multi-agent",$G8)))),"○","対象外") -> ○ | J8: 3 | K8: =IF(OR($H8="対象外",$I8="",$J8=""),"",$J8-$I8) | L8: 4 | M8: 3 | N8: 5 | O8: 5 | P8: 4 | Q8: 2 | R8: =IF(OR($H8="対象外",$K8="",$L8="",$M8="",$N8="",$O8="",$P8="",$Q8=""),"",($K8*$L8*$M8*$N8*$O8*$P8)/$Q8) | S8: =IF($H8="対象外","",IF(OR($I8="",$J8=""),"",IF(OR($J8-$I8>0,AND($R8<>"",$R8>=00_はじめに!$B$19)),"○",""))) | T8: =IFERROR(VLOOKUP($A8,03_質問施策マッピング!$A:$B,2,0),"") -> AIMF-GV-ORG-007 | U8: =IF($T8="","",IFERROR(VLOOKUP($T8,02_施策マスター!$A:$B,2,0),"")) -> AIセキュリティ予算・リソースの確保 | V8: =IF($R8="","",$R8+(1000-ROW())/1000000) | W8: =IF($V8="","",COUNTIF($V$2:$V$208,">"&$V8)+1) | X8: extended
A9: AIMF-GV-ORG-008 | B9: GV | C9: ORG | D9: AIライフサイクル全体のRACI定義 | E9: 企画・開発・評価・運用・廃棄の各フェーズにおける実行責任・説明責任・協業・報告先をRACIとして文書化していますか。 | F9: AI-Enhancement | G9: all | H9: =IF(OR($G9="all",AND(00_はじめに!$B$24="Y",ISNUMBER(SEARCH("traditional",$G9))),AND(00_はじめに!$B$25="Y",ISNUMBER(SEARCH("generative",$G9))),AND(00_はじめに!$B$26="Y",ISNUMBER(SEARCH("ai-agent",$G9))),AND(00_はじめに!$B$27="Y",ISNUMBER(SEARCH("multi-agent",$G9)))),"○","対象外") -> ○ | J9: 3 | K9: =IF(OR($H9="対象外",$I9="",$J9=""),"",$J9-$I9) | L9: 4 | M9: 3 | N9: 5 | O9: 5 | P9: 4 | Q9: 2 | R9: =IF(OR($H9="対象外",$K9="",$L9="",$M9="",$N9="",$O9="",$P9="",$Q9=""),"",($K9*$L9*$M9*$N9*$O9*$P9)/$Q9) | S9: =IF($H9="対象外","",IF(OR($I9="",$J9=""),"",IF(OR($J9-$I9>0,AND($R9<>"",$R9>=00_はじめに!$B$19)),"○",""))) | T9: =IFERROR(VLOOKUP($A9,03_質問施策マッピング!$A:$B,2,0),"") -> AIMF-GV-ORG-008 | U9: =IF($T9="","",IFERROR(VLOOKUP($T9,02_施策マスター!$A:$B,2,0),"")) -> AIライフサイクル全体のRACI定義 | V9: =IF($R9="","",$R9+(1000-ROW())/1000000) | W9: =IF($V9="","",COUNTIF($V$2:$V$208,">"&$V9)+1) | X9: extended
A10: AIMF-GV-ORG-009 | B10: GV | C10: ORG | D10: AI倫理審査との連携プロセス | E10: セキュリティ審査とAI倫理・責任あるAI審査の役割分担と連携手順を定義し、二重審査の漏れと重複を防いでいますか。 | F10: AI-Enhancement | G10: all | H10: =IF(OR($G10="all",AND(00_はじめに!$B$24="Y",ISNUMBER(SEARCH("traditional",$G10))),AND(00_はじめに!$B$25="Y",ISNUMBER(SEARCH("generative",$G10))),AND(00_はじめに!$B$26="Y",ISNUMBER(SEARCH("ai-agent",$G10))),AND(00_はじめに!$B$27="Y",ISNUMBER(SEARCH("multi-agent",$G10)))),"○","対象外") -> ○ | J10: 3 | K10: =IF(OR($H10="対象外",$I10="",$J10=""),"",$J10-$I10) | L10: 4 | M10: 3 | N10: 5 | O10: 5 | P10: 4 | Q10: 2 | R10: =IF(OR($H10="対象外",$K10="",$L10="",$M10="",$N10="",$O10="",$P10="",$Q10=""),"",($K10*$L10*$M10*$N10*$O10*$P10)/$Q10) | S10: =IF($H10="対象外","",IF(OR($I10="",$J10=""),"",IF(OR($J10-$I10>0,AND($R10<>"",$R10>=00_はじめに!$B$19)),"○",""))) | T10: =IFERROR(VLOOKUP($A10,03_質問施策マッピング!$A:$B,2,0),"") -> AIMF-GV-ORG-009 | U10: =IF($T10="","",IFERROR(VLOOKUP($T10,02_施策マスター!$A:$B,2,0),"")) -> AI倫理審査との連携プロセス | V10: =IF($R10="","",$R10+(1000-ROW())/1000000) | W10: =IF($V10="","",COUNTIF($V$2:$V$208,">"&$V10)+1) | X10: extended
A11: AIMF-GV-POL-001 | B11: GV | C11: POL | D11: AIポリシースイートの体系化 | E11: AI利用方針・開発方針・調達方針・データ利用方針を階層的な規程体系として整備し、相互参照と版管理を行っていますか。 | F11: AI-Enhancement | G11: all | H11: =IF(OR($G11="all",AND(00_はじめに!$B$24="Y",ISNUMBER(SEARCH("traditional",$G11))),AND(00_はじめに!$B$25="Y",ISNUMBER(SEARCH("generative",$G11))),AND(00_はじめに!$B$26="Y",ISNUMBER(SEARCH("ai-agent",$G11))),AND(00_はじめに!$B$27="Y",ISNUMBER(SEARCH("multi-agent",$G11)))),"○","対象外") -> ○ | J11: 3 | K11: =IF(OR($H11="対象外",$I11="",$J11=""),"",$J11-$I11) | L11: 4 | M11: 3 | N11: 5 | O11: 5 | P11: 4 | Q11: 2 | R11: =IF(OR($H11="対象外",$K11="",$L11="",$M11="",$N11="",$O11="",$P11="",$Q11=""),"",($K11*$L11*$M11*$N11*$O11*$P11)/$Q11) | S11: =IF($H11="対象外","",IF(OR($I11="",$J11=""),"",IF(OR($J11-$I11>0,AND($R11<>"",$R11>=00_はじめに!$B$19)),"○",""))) | T11: =IFERROR(VLOOKUP($A11,03_質問施策マッピング!$A:$B,2,0),"") -> AIMF-GV-POL-001 | U11: =IF($T11="","",IFERROR(VLOOKUP($T11,02_施策マスター!$A:$B,2,0),"")) -> AIポリシースイートの体系化 | V11: =IF($R11="","",$R11+(1000-ROW())/1000000) | W11: =IF($V11="","",COUNTIF($V$2:$V$208,">"&$V11)+1) | X11: extended
A12: AIMF-GV-POL-002 | B12: GV | C12: POL | D12: 生成AI利用細則（入力禁止情報・プロンプト取扱規程） | E12: 機密情報・個人情報の入力制限、プロンプトの取扱い、出力の業務利用条件を利用者向け細則として定めていますか。 | F12: AI-Expansion | G12: generative-ai | H12: =IF(OR($G12="all",AND(00_はじめに!$B$24="Y",ISNUMBER(SEARCH("traditional",$G12))),AND(00_はじめに!$B$25="Y",ISNUMBER(SEARCH("generative",$G12))),AND(00_はじめに!$B$26="Y",ISNUMBER(SEARCH("ai-agent",$G12))),AND(00_はじめに!$B$27="Y",ISNUMBER(SEARCH("multi-agent",$G12)))),"○","対象外") -> ○ | J12: 3 | K12: =IF(OR($H12="対象外",$I12="",$J12=""),"",$J12-$I12) | L12: 4 | M12: 3 | N12: 5 | O12: 3 | P12: 4 | Q12: 3 | R12: =IF(OR($H12="対象外",$K12="",$L12="",$M12="",$N12="",$O12="",$P12="",$Q12=""),"",($K12*$L12*$M12*$N12*$O12*$P12)/$Q12) | S12: =IF($H12="対象外","",IF(OR($I12="",$J12=""),"",IF(OR($J12-$I12>0,AND($R12<>"",$R12>=00_はじめに!$B$19)),"○",""))) | T12: =IFERROR(VLOOKUP($A12,03_質問施策マッピング!$A:$B,2,0),"") -> AIMF-GV-POL-002 | U12: =IF($T12="","",IFERROR(VLOOKUP($T12,02_施策マスター!$A:$B,2,0),"")) -> 生成AI利用細則（入力禁止情報・プロンプト取扱規程） | V12: =IF($R12="","",$R12+(1000-ROW())/1000000) | W12: =IF($V12="","",COUNTIF($V$2:$V$208,">"&$V12)+1) | X12: extended
A13: AIMF-GV-POL-003 | B13: GV | C13: POL | D13: 承認済みAIサービスカタログと例外管理 | E13: 利用を許可するAIサービス・モデルのカタログを維持し、カタログ外利用の例外承認・期限付き許可プロセスを運用していますか。 | F13: AI-Enhancement | G13: all | H13: =IF(OR($G13="all",AND(00_はじめに!$B$24="Y",ISNUMBER(SEARCH("traditional",$G13))),AND(00_はじめに!$B$25="Y",ISNUMBER(SEARCH("generative",$G13))),AND(00_はじめに!$B$26="Y",ISNUMBER(SEARCH("ai-agent",$G13))),AND(00_はじめに!$B$27="Y",ISNUMBER(SEARCH("multi-agent",$G13)))),"○","対象外") -> ○ | J13: 3 | K13: =IF(OR($H13="対象外",$I13="",$J13=""),"",$J13-$I13) | L13: 4 | M13: 3 | N13: 5 | O13: 5 | P13: 4 | Q13: 2 | R13: =IF(OR($H13="対象外",$K13="",$L13="",$M13="",$N13="",$O13="",$P13="",$Q13=""),"",($K13*$L13*$M13*$N13*$O13*$P13)/$Q13) | S13: =IF($H13="対象外","",IF(OR($I13="",$J13=""),"",IF(OR($J13-$I13>0,AND($R13<>"",$R13>=00_はじめに!$B$19)),"○",""))) | T13: =IFERROR(VLOOKUP($A13,03_質問施策マッピング!$A:$B,2,0),"") -> AIMF-GV-POL-003 | U13: =IF($T13="","",IFERROR(VLOOKUP($T13,02_施策マスター!$A:$B,2,0),"")) -> 承認済みAIサービスカタログと例外管理 | V13: =IF($R13="","",$R13+(1000-ROW())/1000000) | W13: =IF($V13="","",COUNTIF($V$2:$V$208,">"&$V13)+1) | X13: extended
... A208: AIMF-RC-PMM-001 | B208: RC | C208: PMM | D208: 市販後モニタリング計画（Post-market Monitoring） | E208: 提供中のAIシステムについて、性能・堅牢性・インシデント傾向を体系的に収集・分析する市販後モニタリング計画を策定し、リスクマネジメント（GV-1）へフィードバックしていますか。 | F208: AI-Expansion | G208: all | H208: =IF(OR($G208="all",AND(00_はじめに!$B$24="Y",ISNUMBER(SEARCH("traditional",$G208))),AND(00_はじめに!$B$25="Y",ISNUMBER(SEARCH("generative",$G208))),AND(00_はじめに!$B$26="Y",ISNUMBER(SEARCH("ai-agent",$G208))),AND(00_はじめに!$B$27="Y",ISNUMBER(SEARCH("multi-agent",$G208)))),"○","対象外") -> ○ | J208: 4 | K208: =IF(OR($H208="対象外",$I208="",$J208=""),"",$J208-$I208) | L208: 4 | M208: 3 | N208: 5 | O208: 2 | P208: 3 | Q208: 3 | R208: =IF(OR($H208="対象外",$K208="",$L208="",$M208="",$N208="",$O208="",$P208="",$Q208=""),"",($K208*$L208*$M208*$N208*$O208*$P208)/$Q208) | S208: =IF($H208="対象外","",IF(OR($I208="",$J208=""),"",IF(OR($J208-$I208>0,AND($R208<>"",$R208>=00_はじめに!$B$19)),"○",""))) | T208: =IFERROR(VLOOKUP($A208,03_質問施策マッピング!$A:$B,2,0),"") -> AIMF-RC-PMM-001 | U208: =IF($T208="","",IFERROR(VLOOKUP($T208,02_施策マスター!$A:$B,2,0),"")) -> 市販後モニタリング計画（Post-market Monitoring） | V208: =IF($R208="","",$R208+(1000-ROW())/1000000) | W208: =IF($V208="","",COUNTIF($V$2:$V$208,">"&$V208)+1) | X208: baseline

Sheet 02_施策マスター
A1: 施策ID | B1: 施策名 | C1: 区分 | D1: カテゴリ | E1: 施策概要 | F1: 目的 | G1: 期待効果(1-5) | H1: 導入難易度(1-5) | I1: 標準期間(月) | J1: 概算費用区分 | K1: QuickWin係数 | L1: 依存施策ID | M1: control-type | N1: 主な参照基準 | O1: ロードマップ区分 | P1: 優先度補正係数 | Q1: 主担当部門 | R1: 標準成果物 | S1: 顧客説明用価値 | T1: 確認証跡例 | U1: 関連質問ID | V1: introduced-in
A2: AIMF-GV-ORG-001 | B2: AIガバナンス委員会の設置 | C2: GV | D2: ORG | E2: 経営層、CISO、法務、IT部門、事業部門の代表からなるクロスファンクショナルな統治組織を組成し、責任の所在を明確にする。 | F2: ガバナンス・組織体制の確立と文化の醸成に関するリスクを低減し、AIMF GV区分（ORGカテゴリ）の要求に対応する。 | G2: 4 | H2: 2 | I2: 3 | J2: 低 | K2: 1.5 | M2: AI-Enhancement | N2: AI事業者GL, NIST AI RMF, ISO 42001, CSA AICM, EU AI Act | O2: 短期 | P2: 1.2 | Q2: 経営層/リスク管理/法務 | R2: 方針・規程、会議体議事録、リスク登録簿、監査報告 | S2: AIガバナンス委員会の設置により、経営として説明可能なAIガバナンス体制を示せる状態になります。 | T2: 規程・議事録・登録簿・監査記録 | U2: AIMF-GV-ORG-001 | V2: baseline
A3: AIMF-GV-ORG-002 | B3: AI活用基本方針・ガイドラインの策定 | C3: GV | D3: ORG | E3: 全社的なAI利用の目的、許容リスクレベル、禁止事項（機密情報の公衆AIへの入力禁止等）を定義・規程化する。 | F3: ガバナンス・組織体制の確立と文化の醸成に関するリスクを低減し、AIMF GV区分（ORGカテゴリ）の要求に対応する。 | G3: 4 | H3: 2 | I3: 3 | J3: 低 | K3: 1.5 | M3: AI-Enhancement | N3: AI事業者GL, NIST AI RMF, ISO 42001, CSA AICM, NCSC/CISA | O3: 短期 | P3: 1 | Q3: 経営層/リスク管理/法務 | R3: 方針・規程、会議体議事録、リスク登録簿、監査報告 | S3: AI活用基本方針・ガイドラインの策定により、経営として説明可能なAIガバナンス体制を示せる状態になります。 | T3: 規程・議事録・登録簿・監査記録 | U3: AIMF-GV-ORG-002 | V3: baseline
A4: AIMF-GV-ORG-003 | B4: AIリスクアセスメント・プロジェクト承認プロセスの構築 | C4: GV | D4: ORG | E4: 新規AIプロジェクト開始前に機密性・影響度に応じたセキュリティ審査を義務付け、継続的アセスメント体制へシフトする。 | F4: ガバナンス・組織体制の確立と文化の醸成に関するリスクを低減し、AIMF GV区分（ORGカテゴリ）の要求に対応する。 | G4: 4 | H4: 2 | I4: 3 | J4: 低 | K4: 1.5 | M4: AI-Enhancement | N4: NIST AI RMF, ISO 42001, EU AI Act, CSA AICM, NCSC/CISA, AI事業者GL | O4: 短期 | P4: 1.2 | Q4: 経営層/リスク管理/法務 | R4: 方針・規程、会議体議事録、リスク登録簿、監査報告 | S4: AIリスクアセスメント・プロジェクト承認プロセスの構築により、経営として説明可能なAIガバナンス体制を示せる状態になります。 | T4: 規程・議事録・登録簿・監査記録 | U4: AIMF-GV-ORG-003 | V4: baseline
A5: AIMF-GV-ORG-004 | B5: AIセキュリティ文化の醸成 | C5: GV | D5: ORG | E5: 定期的な教育・啓発活動を通じ、全従業員がセキュリティを意識した行動をとれる文化を醸成する。 | F5: ガバナンス・組織体制の確立と文化の醸成に関するリスクを低減し、AIMF GV区分（ORGカテゴリ）の要求に対応する。 | G5: 4 | H5: 2 | I5: 3 | J5: 低 | K5: 1.5 | M5: AI-Enhancement | N5: NIST AI RMF, ISO 42001, AI事業者GL, EU AI Act, CSA AICM | O5: 短期 | P5: 1.2 | Q5: 経営層/リスク管理/法務 | R5: 方針・規程、会議体議事録、リスク登録簿、監査報告 | S5: AIセキュリティ文化の醸成により、経営として説明可能なAIガバナンス体制を示せる状態になります。 | T5: 規程・議事録・登録簿・監査記録 | U5: AIMF-GV-ORG-004 | V5: baseline
A6: AIMF-GV-ORG-005 | B6: AIセキュリティの社内コミュニケーション強化 | C6: GV | D6: ORG | E6: AIセキュリティ情報・インシデントを迅速かつ透明に共有するコミュニケーションチャネルを確立する。 | F6: ガバナンス・組織体制の確立と文化の醸成に関するリスクを低減し、AIMF GV区分（ORGカテゴリ）の要求に対応する。 | G6: 4 | H6: 2 | I6: 3 | J6: 低 | K6: 1.5 | M6: AI-Enhancement | N6: ISO 42001, NIST AI RMF, CSA AICM | O6: 短期 | P6: 1 | Q6: 経営層/リスク管理/法務 | R6: 方針・規程、会議体議事録、リスク登録簿、監査報告 | S6: AIセキュリティの社内コミュニケーション強化により、経営として説明可能なAIガバナンス体制を示せる状態になります。 | T6: 規程・議事録・登録簿・監査記録 | U6: AIMF-GV-ORG-005 | V6: baseline
A7: AIMF-GV-ORG-006 | B7: AI統括責任者（CAIO/AIセキュリティ責任者）の任命 | C7: GV | D7: ORG | E7: AIのリスクとセキュリティに関する説明責任を負う役員級の責任者を任命し、取締役会への定期報告ラインを確立する。 | F7: ガバナンス・組織体制の確立と文化の醸成に関するリスクを低減し、AIMF GV区分（ORGカテゴリ）の要求に対応する。 | G7: 4 | H7: 2 | I7: 3 | J7: 低 | K7: 1.5 | M7: AI-Enhancement | N7: NIST AI RMF, ISO 42001, Five Eyes声明, SANS AIMM | O7: 短期 | P7: 1 | Q7: 経営層/リスク管理/法務 | R7: 方針・規程、会議体議事録、リスク登録簿、監査報告 | S7: AI統括責任者（CAIO/AIセキュリティ責任者）の任命により、経営として説明可能なAIガバナンス体制を示せる状態になります。 | T7: 規程・議事録・登録簿・監査記録 | U7: AIMF-GV-ORG-006 | V7: extended
A8: AIMF-GV-ORG-007 | B8: AIセキュリティ予算・リソースの確保 | C8: GV | D8: ORG | E8: AI脅威の進展速度に見合うセキュリティ投資（人員・ツール・訓練）を経営レベルで確保し、毎年見直す。 | F8: ガバナンス・組織体制の確立と文化の醸成に関するリスクを低減し、AIMF GV区分（ORGカテゴリ）の要求に対応する。 | G8: 4 | H8: 2 | I8: 3 | J8: 低 | K8: 1.5 | M8: AI-Enhancement | N8: Five Eyes声明, NIST AI RMF, CSA AICM | O8: 短期 | P8: 1 | Q8: 経営層/リスク管理/法務 | R8: 方針・規程、会議体議事録、リスク登録簿、監査報告 | S8: AIセキュリティ予算・リソースの確保により、経営として説明可能なAIガバナンス体制を示せる状態になります。 | T8: 規程・議事録・登録簿・監査記録 | U8: AIMF-GV-ORG-007 | V8: extended
A9: AIMF-GV-ORG-008 | B9: AIライフサイクル全体のRACI定義 | C9: GV | D9: ORG | E9: 企画・開発・評価・運用・廃棄の各フェーズにおける実行責任・説明責任・協業・報告先をRACIとして文書化する。 | F9: ガバナンス・組織体制の確立と文化の醸成に関するリスクを低減し、AIMF GV区分（ORGカテゴリ）の要求に対応する。 | G9: 4 | H9: 2 | I9: 3 | J9: 低 | K9: 1.5 | M9: AI-Enhancement | N9: ISO 42001, NIST AI RMF, ASDエージェントAI | O9: 短期 | P9: 1 | Q9: 経営層/リスク管理/法務 | R9: 方針・規程、会議体議事録、リスク登録簿、監査報告 | S9: AIライフサイクル全体のRACI定義により、経営として説明可能なAIガバナンス体制を示せる状態になります。 | T9: 規程・議事録・登録簿・監査記録 | U9: AIMF-GV-ORG-008 | V9: extended
A10: AIMF-GV-ORG-009 | B10: AI倫理審査との連携プロセス | C10: GV | D10: ORG | E10: セキュリティ審査とAI倫理・責任あるAI審査の役割分担と連携手順を定義し、二重審査の漏れと重複を防ぐ。 | F10: ガバナンス・組織体制の確立と文化の醸成に関するリスクを低減し、AIMF GV区分（ORGカテゴリ）の要求に対応する。 | G10: 4 | H10: 2 | I10: 3 | J10: 低 | K10: 1.5 | M10: AI-Enhancement | N10: AI事業者GL, ISO 42001, NIST AI RMF | O10: 短期 | P10: 1 | Q10: 経営層/リスク管理/法務 | R10: 方針・規程、会議体議事録、リスク登録簿、監査報告 | S10: AI倫理審査との連携プロセスにより、経営として説明可能なAIガバナンス体制を示せる状態になります。 | T10: 規程・議事録・登録簿・監査記録 | U10: AIMF-GV-ORG-009 | V10: extended
A11: AIMF-GV-POL-001 | B11: AIポリシースイートの体系化 | C11: GV | D11: POL | E11: AI利用方針・開発方針・調達方針・データ利用方針を階層的な規程体系として整備し、相互参照と版管理を行う。 | F11: AI方針・規程体系に関するリスクを低減し、AIMF GV区分（POLカテゴリ）の要求に対応する。 | G11: 4 | H11: 2 | I11: 3 | J11: 低 | K11: 1.5 | M11: AI-Enhancement | N11: ISO 42001, NIST AI RMF, SANS AIMM | O11: 短期 | P11: 1 | Q11: 経営層/リスク管理/法務 | R11: 方針・規程、会議体議事録、リスク登録簿、監査報告 | S11: AIポリシースイートの体系化により、経営として説明可能なAIガバナンス体制を示せる状態になります。 | T11: 規程・議事録・登録簿・監査記録 | U11: AIMF-GV-POL-001 | V11: extended
A12: AIMF-GV-POL-002 | B12: 生成AI利用細則（入力禁止情報・プロンプト取扱規程） | C12: GV | D12: POL | E12: 機密情報・個人情報の入力制限、プロンプトの取扱い、出力の業務利用条件を利用者向け細則として定める。 | F12: AI方針・規程体系に関するリスクを低減し、AIMF GV区分（POLカテゴリ）の要求に対応する。 | G12: 4 | H12: 3 | I12: 6 | J12: 中 | K12: 1.2 | M12: AI-Expansion | N12: デジタル庁GL, AI事業者GL, 総務省AIセキュリティGL | O12: 中期 | P12: 1 | Q12: 経営層/リスク管理/法務 | R12: 方針・規程、会議体議事録、リスク登録簿、監査報告 | S12: 生成AI利用細則（入力禁止情報・プロンプト取扱規程）により、経営として説明可能なAIガバナンス体制を示せる状態になります。 | T12: 規程・議事録・登録簿・監査記録 | U12: AIMF-GV-POL-002 | V12: extended
A13: AIMF-GV-POL-003 | B13: 承認済みAIサービスカタログと例外管理 | C13: GV | D13: POL | E13: 利用を許可するAIサービス・モデルのカタログを維持し、カタログ外利用の例外承認・期限付き許可プロセスを運用する。 | F13: AI方針・規程体系に関するリスクを低減し、AIMF GV区分（POLカテゴリ）の要求に対応する。 | G13: 4 | H13: 2 | I13: 3 | J13: 低 | K13: 1.5 | M13: AI-Enhancement | N13: CIS v8.1, NIST AI RMF, デジタル庁GL | O13: 短期 | P13: 1 | Q13: 経営層/リスク管理/法務 | R13: 方針・規程、会議体議事録、リスク登録簿、監査報告 | S13: 承認済みAIサービスカタログと例外管理により、経営として説明可能なAIガバナンス体制を示せる状態になります。 | T13: 規程・議事録・登録簿・監査記録 | U13: AIMF-GV-POL-003 | V13: extended
... A78: AIMF-PR-INF-007 | B78: AIリソース設定のセキュリティベースライン | C78: PR | D78: INF | E78: ベクトルDB・推論サーバー・オーケストレーターのセキュア設定基準を定義し、IaCスキャンで逸脱を継続検出する。 | F78: AIインフラ・ネットワークの要塞化に関するリスクを低減し、AIMF PR区分（INFカテゴリ）の要求に対応する。 | G78: 4 | H78: 3 | I78: 6 | J78: 中 | K78: 1.5 | M78: AI-Enhancement | N78: CIS v8.1, CSA AICM, ASDエージェントAI | O78: 中期 | P78: 1 | Q78: セキュリティ部門/AI開発/IT基盤 | R78: 設計書、設定記録、評価レポート、教育記録 | S78: AIリソース設定のセキュリティベースラインにより、AI固有の攻撃・誤動作を未然に防ぐ実装統制が整います。 | T78: 設定画面・テスト結果・パイプライン定義 | U78: AIMF-PR-INF-007 | V78: extended
A79: AIMF-PR-IAM-001 | B79: RAGデータアクセス権（ACL）の同期 | C79: PR | D79: IAM | E79: 社内のアイデンティティ／ファイル権限とRAGのベクトルDBを完全同期し、閲覧権限を超えた情報のプロンプト混入をシステム的に防ぐ。 | F79: アイデンティティ・アクセス制御に関するリスクを低減し、AIMF PR区分（IAMカテゴリ）の要求に対応する。 | G79: 5 | H79: 4 | I79: 9 | J79: 高 | K79: 1 | L79: AIMF-ID-AST-002 | M79: AI-Expansion | N79: OWASP AISVS, CSA AICM, 総務省AIセキュリティGL, EU AI Act, NCSC/CISA, NIST AI RMF | O79: 長期 | P79: 1.2 | Q79: セキュリティ部門/AI開発/IT基盤 | R79: 設計書、設定記録、評価レポート、教育記録 | S79: RAGデータアクセス権（ACL）の同期により、AI固有の攻撃・誤動作を未然に防ぐ実装統制が整います。 | T79: 設定画面・テスト結果・パイプライン定義 | U79: AIMF-PR-IAM-001 | V79: baseline
A80: AIMF-PR-IAM-002 | B80: AIエージェントへの最小権限原則の適用 | C80: PR | D80: IAM | E80: 自律エージェントに付与するAPIキー・操作権限を担当業務に必要な最小限に制限する。 | F80: アイデンティティ・アクセス制御に関するリスクを低減し、AIMF PR区分（IAMカテゴリ）の要求に対応する。 | G80: 5 | H80: 4 | I80: 9 | J80: 高 | K80: 1 | L80: AIMF-ID-AST-003 | M80: AI-Expansion | N80: OWASP AISVS, CSA AICM, NCSC/CISA, EU AI Act | O80: 長期 | P80: 1.2 | Q80: セキュリティ部門/AI開発/IT基盤 | R80: 設計書、設定記録、評価レポート、教育記録 | S80: AIエージェントへの最小権限原則の適用により、AI固有の攻撃・誤動作を未然に防ぐ実装統制が整います。 | T80: 設定画面・テスト結果・パイプライン定義 | U80: AIMF-PR-IAM-002 | V80: baseline
A81: AIMF-PR-IAM-003 | B81: AIクレデンシャル・APIキーの暗号化管理 | C81: PR | D81: IAM | E81: 各種キーをハードコードせず、シークレットマネージャーで暗号化し動的に呼び出す。 | F81: アイデンティティ・アクセス制御に関するリスクを低減し、AIMF PR区分（IAMカテゴリ）の要求に対応する。 | G81: 5 | H81: 3 | I81: 6 | J81: 中 | K81: 1.5 | M81: AI-Enhancement | N81: OWASP AISVS, CSA AICM, 総務省AIセキュリティGL, NCSC/CISA | O81: 中期 | P81: 1 | Q81: セキュリティ部門/AI開発/IT基盤 | R81: 設計書、設定記録、評価レポート、教育記録 | S81: AIクレデンシャル・APIキーの暗号化管理により、AI固有の攻撃・誤動作を未然に防ぐ実装統制が整います。 | T81: 設定画面・テスト結果・パイプライン定義 | U81: AIMF-PR-IAM-003 | V81: baseline
A82: AIMF-PR-IAM-004 | B82: フィッシング耐性MFAの適用（AI管理者・特権） | C82: PR | D82: IAM | E82: AI基盤の管理者・モデルレジストリ・学習パイプラインへのアクセスにフィッシング耐性認証（AAL2以上、パスキー/FIDO2等）を義務付ける。 | F82: アイデンティティ・アクセス制御に関するリスクを低減し、AIMF PR区分（IAMカテゴリ）の要求に対応する。 | G82: 5 | H82: 3 | I82: 6 | J82: 中 | K82: 1.5 | M82: AI-Enhancement | N82: NIST 800-63-4, CIS v8.1, Five Eyes声明 | O82: 中期 | P82: 1 | Q82: セキュリティ部門/AI開発/IT基盤 | R82: 設計書、設定記録、評価レポート、教育記録 | S82: フィッシング耐性MFAの適用（AI管理者・特権）により、AI固有の攻撃・誤動作を未然に防ぐ実装統制が整います。 | T82: 設定画面・テスト結果・パイプライン定義 | U82: AIMF-PR-IAM-004 | V82: extended
A83: AIMF-PR-IAM-005 | B83: エージェント・サービスアカウントのライフサイクル管理 | C83: PR | D83: IAM | E83: 各エージェントに専用の非人間アイデンティティを発行し、作成・権限変更・棚卸し・廃止をライフサイクル管理する。 | F83: アイデンティティ・アクセス制御に関するリスクを低減し、AIMF PR区分（IAMカテゴリ）の要求に対応する。 | G83: 5 | H83: 4 | I83: 9 | J83: 高 | K83: 1 | M83: AI-Expansion | N83: OWASP ASI10, NIST 800-63-4, CSA AICM | O83: 長期 | P83: 1 | Q83: セキュリティ部門/AI開発/IT基盤 | R83: 設計書、設定記録、評価レポート、教育記録 | S83: エージェント・サービスアカウントのライフサイクル管理により、AI固有の攻撃・誤動作を未然に防ぐ実装統制が整います。 | T83: 設定画面・テスト結果・パイプライン定義 | U83: AIMF-PR-IAM-005 | V83: extended
A84: AIMF-PR-IAM-006 | B84: 短命トークン・タスクバウンド認可 | C84: PR | D84: IAM | E84: エージェントの認可を短命トークンとタスク単位のスコープに限定し、恒久的な広域クレデンシャルの付与を禁止する。 | F84: アイデンティティ・アクセス制御に関するリスクを低減し、AIMF PR区分（IAMカテゴリ）の要求に対応する。 | G84: 5 | H84: 4 | I84: 9 | J84: 高 | K84: 1 | L84: AIMF-PR-IAM-005 | M84: AI-Expansion | N84: OWASP ASI10, ASDエージェントAI | O84: 長期 | P84: 1 | Q84: セキュリティ部門/AI開発/IT基盤 | R84: 設計書、設定記録、評価レポート、教育記録 | S84: 短命トークン・タスクバウンド認可により、AI固有の攻撃・誤動作を未然に防ぐ実装統制が整います。 | T84: 設定画面・テスト結果・パイプライン定義 | U84: AIMF-PR-IAM-006 | V84: extended
A85: AIMF-PR-IAM-007 | B85: 動的な権限昇格の禁止とJITアクセス | C85: PR | D85: IAM | E85: エージェントによる実行時の権限昇格・スコープ拡大を禁止し、例外は人間承認付きのJIT（Just-in-Time）アクセスに限定する。 | F85: アイデンティティ・アクセス制御に関するリスクを低減し、AIMF PR区分（IAMカテゴリ）の要求に対応する。 | G85: 5 | H85: 4 | I85: 9 | J85: 高 | K85: 1 | M85: AI-Expansion | N85: OWASP ASI10, CIS v8.1, ASDエージェントAI | O85: 長期 | P85: 1 | Q85: セキュリティ部門/AI開発/IT基盤 | R85: 設計書、設定記録、評価レポート、教育記録 | S85: 動的な権限昇格の禁止とJITアクセスにより、AI固有の攻撃・誤動作を未然に防ぐ実装統制が整います。 | T85: 設定画面・テスト結果・パイプライン定義 | U85: AIMF-PR-IAM-007 | V85: extended
A86: AIMF-PR-IAM-008 | B86: AIプラットフォームのRBAC/ABAC設計 | C86: PR | D86: IAM | E86: モデル・データセット・プロンプト・評価結果への操作権限をロール・属性ベースで設計し、職務分離を実装する。 | F86: アイデンティティ・アクセス制御に関するリスクを低減し、AIMF PR区分（IAMカテゴリ）の要求に対応する。 | G86: 5 | H86: 3 | I86: 6 | J86: 中 | K86: 1.5 | M86: AI-Enhancement | N86: OWASP AISVS, CIS v8.1, CSA AICM | O86: 中期 | P86: 1 | Q86: セキュリティ部門/AI開発/IT基盤 | R86: 設計書、設定記録、評価レポート、教育記録 | S86: AIプラットフォームのRBAC/ABAC設計により、AI固有の攻撃・誤動作を未然に防ぐ実装統制が整います。 | T86: 設定画面・テスト結果・パイプライン定義 | U86: AIMF-PR-IAM-008 | V86: extended
A87: AIMF-PR-DAT-001 | B87: プロンプト・出力へのDLP統制 | C87: PR | D87: DAT | E87: プロンプト入力および出力経路にDLPを適用し、機密情報・個人情報の外部AIサービスへの送信と出力経由の漏えいを制御する。 | F87: AIデータ保護に関するリスクを低減し、AIMF PR区分（DATカテゴリ）の要求に対応する。 | G87: 5 | H87: 4 | I87: 9 | J87: 高 | K87: 1 | M87: AI-Expansion | N87: CIS v8.1, デジタル庁GL, OWASP AISVS | O87: 長期 | P87: 1 | Q87: セキュリティ部門/AI開発/IT基盤 | R87: 設計書、設定記録、評価レポート、教育記録 | S87: プロンプト・出力へのDLP統制により、AI固有の攻撃・誤動作を未然に防ぐ実装統制が整います。 | T87: 設定画面・テスト結果・パイプライン定義 | U87: AIMF-PR-DAT-001 | V87: extended
A88: AIMF-PR-DAT-002 | B88: 学習・RAG投入前の仮名化・匿名化 | C88: PR | D88: DAT | E88: 学習・RAGへ投入する個人データに仮名化・匿名化・トークナイゼーションを適用し、再識別リスクを評価する。 | F88: AIデータ保護に関するリスクを低減し、AIMF PR区分（DATカテゴリ）の要求に対応する。 | G88: 5 | H88: 4 | I88: 9 | J88: 高 | K88: 1 | M88: AI-Expansion | N88: OWASP AISVS, EU AI Act, ISO 42001 | O88: 長期 | P88: 1.2 | Q88: セキュリティ部門/AI開発/IT基盤 | R88: 設計書、設定記録、評価レポート、教育記録 | S88: 学習・RAG投入前の仮名化・匿名化により、AI固有の攻撃・誤動作を未然に防ぐ実装統制が整います。 | T88: 設定画面・テスト結果・パイプライン定義 | U88: AIMF-PR-DAT-002 | V88: extended
A89: AIMF-PR-DAT-003 | B89: 出力データへの機密区分の継承 | C89: PR | D89: DAT | E89: 機密データを参照して生成された出力に元データの機密区分を継承させ、取扱い・保存・共有の制限を適用する。 | F89: AIデータ保護に関するリスクを低減し、AIMF PR区分（DATカテゴリ）の要求に対応する。 | G89: 5 | H89: 4 | I89: 9 | J89: 高 | K89: 1 | M89: AI-Expansion | N89: CIS v8.1, ISO 42001, OWASP AISVS | O89: 長期 | P89: 1 | Q89: セキュリティ部門/AI開発/IT基盤 | R89: 設計書、設定記録、評価レポート、教育記録 | S89: 出力データへの機密区分の継承により、AI固有の攻撃・誤動作を未然に防ぐ実装統制が整います。 | T89: 設定画面・テスト結果・パイプライン定義 | U89: AIMF-PR-DAT-003 | V89: extended
A90: AIMF-PR-DAT-004 | B90: モデル重み・チェックポイントの厳格アクセス管理 | C90: PR | D90: DAT | E90: モデル重み・チェックポイント・アダプタへのアクセスを職務上必要な主体に限定し、持出し検知と併せて知財流出を防ぐ。 | F90: AIデータ保護に関するリスクを低減し、AIMF PR区分（DATカテゴリ）の要求に対応する。 | G90: 5 | H90: 4 | I90: 9 | J90: 高 | K90: 1 | M90: AI-Expansion | N90: NCSC/CISA, OWASP AISVS, MITRE ATLAS | O90: 長期 | P90: 1 | Q90: セキュリティ部門/AI開発/IT基盤 | R90: 設計書、設定記録、評価レポート、教育記録 | S90: モデル重み・チェックポイントの厳格アクセス管理により、AI固有の攻撃・誤動作を未然に防ぐ実装統制が整います。 | T90: 設定画面・テスト結果・パイプライン定義 | U90: AIMF-PR-DAT-004 | V90: extended
A91: AIMF-PR-DAT-005 | B91: 機密コンピューティングによる推論保護 | C91: PR | D91: DAT | E91: 高機微ユースケースにおいて、TEE等の機密コンピューティングにより推論時のデータ・モデルをメモリ上でも保護する。 | F91: AIデータ保護に関するリスクを低減し、AIMF PR区分（DATカテゴリ）の要求に対応する。 | G91: 5 | H91: 4 | I91: 9 | J91: 高 | K91: 1 | M91: AI-Expansion | N91: CSA AICM, NCSC/CISA | O91: 長期 | P91: 1 | Q91: セキュリティ部門/AI開発/IT基盤 | R91: 設計書、設定記録、評価レポート、教育記録 | S91: 機密コンピューティングによる推論保護により、AI固有の攻撃・誤動作を未然に防ぐ実装統制が整います。 | T91: 設定画面・テスト結果・パイプライン定義 | U91: AIMF-PR-DAT-005 | V91: extended
A92: AIMF-PR-MDL-001 | B92: モデルライフサイクル管理・リリース前評価 | C92: PR | D92: MDL | E92: モデル・プロンプト・設定の変更管理、リリース前のセキュリティ／性能受入基準、承認ゲート、ロールバック手順を定義する。 | F92: モデルライフサイクル・成果物完全性に関するリスクを低減し、AIMF PR区分（MDLカテゴリ）の要求に対応する。 | G92: 4 | H92: 4 | I92: 9 | J92: 高 | K92: 1 | M92: AI-Expansion | N92: OWASP AISVS, ISO 42001, NCSC/CISA, EU AI Act, NIST AI RMF, 総務省AIセキュリティGL | O92: 長期 | P92: 1.2 | Q92: セキュリティ部門/AI開発/IT基盤 | R92: 設計書、設定記録、評価レポート、教育記録 | S92: モデルライフサイクル管理・リリース前評価により、AI固有の攻撃・誤動作を未然に防ぐ実装統制が整います。 | T92: 設定画面・テスト結果・パイプライン定義 | U92: AIMF-PR-MDL-001 | V92: baseline
A93: AIMF-PR-MDL-002 | B93: モデル成果物の完全性保護 | C93: PR | D93: MDL | E93: モデルファイルの署名・ハッシュ検証、安全でないデシリアライゼーション（pickle等）対策、モデルリポジトリからの取得時のTrojan/悪性レイヤースキャンを実装する。 | F93: モデルライフサイクル・成果物完全性に関するリスクを低減し、AIMF PR区分（MDLカテゴリ）の要求に対応する。 | G93: 4 | H93: 4 | I93: 9 | J93: 高 | K93: 1 | M93: AI-Expansion | N93: OWASP AISVS, NCSC/CISA, CSA AICM, 総務省AIセキュリティGL | O93: 長期 | P93: 1 | Q93: セキュリティ部門/AI開発/IT基盤 | R93: 設計書、設定記録、評価レポート、教育記録 | S93: モデル成果物の完全性保護により、AI固有の攻撃・誤動作を未然に防ぐ実装統制が整います。 | T93: 設定画面・テスト結果・パイプライン定義 | U93: AIMF-PR-MDL-002 | V93: baseline
A94: AIMF-PR-MDL-003 | B94: セキュア学習パイプラインの統制 | C94: PR | D94: MDL | E94: 学習ジョブの実行権限・データアクセス・成果物出力を統制し、パイプライン定義自体を版管理・レビュー対象とする。 | F94: モデルライフサイクル・成果物完全性に関するリスクを低減し、AIMF PR区分（MDLカテゴリ）の要求に対応する。 | G94: 4 | H94: 4 | I94: 9 | J94: 高 | K94: 1 | M94: AI-Expansion | N94: OWASP AISVS, NCSC/CISA, CIS v8.1 | O94: 長期 | P94: 1 | Q94: セキュリティ部門/AI開発/IT基盤 | R94: 設計書、設定記録、評価レポート、教育記録 | S94: セキュア学習パイプラインの統制により、AI固有の攻撃・誤動作を未然に防ぐ実装統制が整います。 | T94: 設定画面・テスト結果・パイプライン定義 | U94: AIMF-PR-MDL-003 | V94: extended
A95: AIMF-PR-MDL-004 | B95: モデルレジストリ統制（承認済みモデルのみデプロイ） | C95: PR | D95: MDL | E95: 本番デプロイをレジストリ登録済み・承認済み・署名検証済みのモデルに限定し、レジストリ外モデルの実行を技術的に遮断する。 | F95: モデルライフサイクル・成果物完全性に関するリスクを低減し、AIMF PR区分（MDLカテゴリ）の要求に対応する。 | G95: 4 | H95: 4 | I95: 9 | J95: 高 | K95: 1 | L95: AIMF-ID-SCM-003 | M95: AI-Expansion | N95: OWASP AISVS, NCSC/CISA | O95: 長期 | P95: 1 | Q95: セキュリティ部門/AI開発/IT基盤 | R95: 設計書、設定記録、評価レポート、教育記録 | S95: モデルレジストリ統制（承認済みモデルのみデプロイ）により、AI固有の攻撃・誤動作を未然に防ぐ実装統制が整います。 | T95: 設定画面・テスト結果・パイプライン定義 | U95: AIMF-PR-MDL-004 | V95: extended
A96: AIMF-PR-MDL-005 | B96: ファインチューニング・継続学習の変更管理 | C96: PR | D96: MDL | E96: ファインチューニング・RLHF・継続学習を変更管理の対象とし、実施前のデータ審査と実施後の安全性再評価を義務付ける。 | F96: モデルライフサイクル・成果物完全性に関するリスクを低減し、AIMF PR区分（MDLカテゴリ）の要求に対応する。 | G96: 4 | H96: 4 | I96: 9 | J96: 高 | K96: 1 | M96: AI-Expansion | N96: OWASP AISVS, EU AI Act, NIST AI RMF | O96: 長期 | P96: 1.2 | Q96: セキュリティ部門/AI開発/IT基盤 | R96: 設計書、設定記録、評価レポート、教育記録 | S96: ファインチューニング・継続学習の変更管理により、AI固有の攻撃・誤動作を未然に防ぐ実装統制が整います。 | T96: 設定画面・テスト結果・パイプライン定義 | U96: AIMF-PR-MDL-005 | V96: extended
A97: AIMF-PR-MDL-006 | B97: 量子化・蒸留・最適化後の安全性再評価 | C97: PR | D97: MDL | E97: 量子化・蒸留・プルーニング等の最適化後に、安全性・ガードレール有効性・堅牢性の劣化がないことを再評価する。 | F97: モデルライフサイクル・成果物完全性に関するリスクを低減し、AIMF PR区分（MDLカテゴリ）の要求に対応する。 | G97: 4 | H97: 4 | I97: 9 | J97: 高 | K97: 1 | M97: AI-Expansion | N97: OWASP AISVS, NIST AI RMF | O97: 長期 | P97: 1 | Q97: セキュリティ部門/AI開発/IT基盤 | R97: 設計書、設定記録、評価レポート、教育記録 | S97: 量子化・蒸留・最適化後の安全性再評価により、AI固有の攻撃・誤動作を未然に防ぐ実装統制が整います。 | T97: 設定画面・テスト結果・パイプライン定義 | U97: AIMF-PR-MDL-006 | V97: extended
A98: AIMF-PR-MDL-007 | B98: システムプロンプトの版管理と保護 | C98: PR | D98: MDL | E98: システムプロンプトを機密構成情報として版管理・アクセス制限し、機密情報や認可ロジックをプロンプト内に置かない設計を強制する。 | F98: モデルライフサイクル・成果物完全性に関するリスクを低減し、AIMF PR区分（MDLカテゴリ）の要求に対応する。 | G98: 4 | H98: 4 | I98: 9 | J98: 高 | K98: 1 | M98: AI-Expansion | N98: OWASP LLM10, OWASP AISVS, 総務省AIセキュリティGL | O98: 長期 | P98: 1 | Q98: セキュリティ部門/AI開発/IT基盤 | R98: 設計書、設定記録、評価レポート、教育記録 | S98: システムプロンプトの版管理と保護により、AI固有の攻撃・誤動作を未然に防ぐ実装統制が整います。 | T98: 設定画面・テスト結果・パイプライン定義 | U98: AIMF-PR-MDL-007 | V98: extended
A99: AIMF-PR-RED-001 | B99: AIレッドチーミングの定期的実施 | C99: PR | D99: RED | E99: 専門チームが擬似攻撃者として脱獄や間接的プロンプトインジェクションを試行し、稼働前システムの脆弱性を洗い出す。 | F99: プロアクティブなリスク評価・実戦演習に関するリスクを低減し、AIMF PR区分（REDカテゴリ）の要求に対応する。 | G99: 4 | H99: 4 | I99: 9 | J99: 高 | K99: 1 | M99: AI-Expansion | N99: NIST AI RMF, EU AI Act, OWASP AISVS, 総務省AIセキュリティGL, ISO 42001, CSA AICM, NCSC/CISA, AI事業者GL | O99: 長期 | P99: 1.2 | Q99: セキュリティ部門/AI開発/IT基盤 | R99: 設計書、設定記録、評価レポート、教育記録 | S99: AIレッドチーミングの定期的実施により、AI固有の攻撃・誤動作を未然に防ぐ実装統制が整います。 | T99: 設定画面・テスト結果・パイプライン定義 | U99: AIMF-PR-RED-001 | V99: baseline
A100: AIMF-PR-RED-002 | B100: 自動化されたAI脆弱性スキャン（LLM-assisted Red Teaming） | C100: PR | D100: RED | E100: 攻撃用にチューニングしたAIエージェントで攻撃プロンプトを高速自動投入し、脱獄パターンを継続的・網羅的に探索する。 | F100: プロアクティブなリスク評価・実戦演習に関するリスクを低減し、AIMF PR区分（REDカテゴリ）の要求に対応する。 | G100: 4 | H100: 4 | I100: 9 | J100: 高 | K100: 1 | M100: AI-Expansion | N100: OWASP AISVS, CSA AICM, 総務省AIセキュリティGL | O100: 長期 | P100: 1 | Q100: セキュリティ部門/AI開発/IT基盤 | R100: 設計書、設定記録、評価レポート、教育記録 | S100: 自動化されたAI脆弱性スキャン（LLM-assisted Red Teaming）により、AI固有の攻撃・誤動作を未然に防ぐ実装統制が整います。 | T100: 設定画面・テスト結果・パイプライン定義 | U100: AIMF-PR-RED-002 | V100: baseline
A101: AIMF-PR-RED-003 | B101: RAG知識ベースの動的スキャン | C101: PR | D101: RED | E101: 検索対象のファイルサーバー・DBを常時スキャンし、不正プロンプト（ポイズニングデータ）や誤格納された機密情報を自動検知・隔離する。 | F101: プロアクティブなリスク評価・実戦演習に関するリスクを低減し、AIMF PR区分（REDカテゴリ）の要求に対応する。 | G101: 4 | H101: 4 | I101: 9 | J101: 高 | K101: 1 | M101: AI-Expansion | N101: OWASP AISVS, 総務省AIセキュリティGL, CSA AICM | O101: 長期 | P101: 1 | Q101: セキュリティ部門/AI開発/IT基盤 | R101: 設計書、設定記録、評価レポート、教育記録 | S101: RAG知識ベースの動的スキャンにより、AI固有の攻撃・誤動作を未然に防ぐ実装統制が整います。 | T101: 設定画面・テスト結果・パイプライン定義 | U101: AIMF-PR-RED-003 | V101: baseline
A102: AIMF-PR-RED-004 | B102: リリース前の安全性・セキュリティ評価スイート | C102: PR | D102: RED | E102: リリース前にベンチマーク・有害性評価・セキュリティ評価からなる標準評価スイートを実行し、受入基準への適合を承認条件とする。 | F102: プロアクティブなリスク評価・実戦演習に関するリスクを低減し、AIMF PR区分（REDカテゴリ）の要求に対応する。 | G102: 4 | H102: 4 | I102: 9 | J102: 高 | K102: 1 | M102: AI-Expansion | N102: NIST AI RMF, EU AI Act, NCSC/CISA | O102: 長期 | P102: 1.2 | Q102: セキュリティ部門/AI開発/IT基盤 | R102: 設計書、設定記録、評価レポート、教育記録 | S102: リリース前の安全性・セキュリティ評価スイートにより、AI固有の攻撃・誤動作を未然に防ぐ実装統制が整います。 | T102: 設定画面・テスト結果・パイプライン定義 | U102: AIMF-PR-RED-004 | V102: extended
A103: AIMF-PR-RED-005 | B103: CI/CDへの継続的評価（eval）の組み込み | C103: PR | D103: RED | E103: モデル・プロンプト・ガードレールの変更ごとに自動評価をCI/CDで実行し、回帰（安全性低下）を検出してデプロイを停止する。 | F103: プロアクティブなリスク評価・実戦演習に関するリスクを低減し、AIMF PR区分（REDカテゴリ）の要求に対応する。 | G103: 4 | H103: 4 | I103: 9 | J103: 高 | K103: 1 | L103: AIMF-PR-RED-004 | M103: AI-Expansion | N103: OWASP AISVS, NIST AI RMF | O103: 長期 | P103: 1 | Q103: セキュリティ部門/AI開発/IT基盤 | R103: 設計書、設定記録、評価レポート、教育記録 | S103: CI/CDへの継続的評価（eval）の組み込みにより、AI固有の攻撃・誤動作を未然に防ぐ実装統制が整います。 | T103: 設定画面・テスト結果・パイプライン定義 | U103: AIMF-PR-RED-005 | V103: extended
A104: AIMF-PR-RED-006 | B104: ATLASベースの敵対的演習 | C104: PR | D104: RED | E104: ATLASのTTPに基づく攻撃シナリオでパープルチーミングを実施し、防御と検知の実効性を同時に検証する。 | F104: プロアクティブなリスク評価・実戦演習に関するリスクを低減し、AIMF PR区分（REDカテゴリ）の要求に対応する。 | G104: 4 | H104: 4 | I104: 9 | J104: 高 | K104: 1 | M104: AI-Expansion | N104: MITRE ATLAS, CIS v8.1, NCSC/CISA | O104: 長期 | P104: 1 | Q104: セキュリティ部門/AI開発/IT基盤 | R104: 設計書、設定記録、評価レポート、教育記録 | S104: ATLASベースの敵対的演習により、AI固有の攻撃・誤動作を未然に防ぐ実装統制が整います。 | T104: 設定画面・テスト結果・パイプライン定義 | U104: AIMF-PR-RED-006 | V104: extended
...

Sheet 03_質問施策マッピング
A1: 質問ID | B1: 候補施策ID | C1: 候補施策名 | D1: 区分 | E1: マッピング理由 | F1: 優先抽出条件
A2: AIMF-GV-ORG-001 | B2: AIMF-GV-ORG-001 | C2: AIガバナンス委員会の設置 | D2: GV | E2: 質問はコントロール実装状況を問うため、同一コントロールの実装施策と1:1で対応する。 | F2: 現状評価が目標評価未満、または優先度スコアが閾値以上（対象外を除く）
A3: AIMF-GV-ORG-002 | B3: AIMF-GV-ORG-002 | C3: AI活用基本方針・ガイドラインの策定 | D3: GV | E3: 質問はコントロール実装状況を問うため、同一コントロールの実装施策と1:1で対応する。 | F3: 現状評価が目標評価未満、または優先度スコアが閾値以上（対象外を除く）
A4: AIMF-GV-ORG-003 | B4: AIMF-GV-ORG-003 | C4: AIリスクアセスメント・プロジェクト承認プロセスの構築 | D4: GV | E4: 質問はコントロール実装状況を問うため、同一コントロールの実装施策と1:1で対応する。 | F4: 現状評価が目標評価未満、または優先度スコアが閾値以上（対象外を除く）
A5: AIMF-GV-ORG-004 | B5: AIMF-GV-ORG-004 | C5: AIセキュリティ文化の醸成 | D5: GV | E5: 質問はコントロール実装状況を問うため、同一コントロールの実装施策と1:1で対応する。 | F5: 現状評価が目標評価未満、または優先度スコアが閾値以上（対象外を除く）
A6: AIMF-GV-ORG-005 | B6: AIMF-GV-ORG-005 | C6: AIセキュリティの社内コミュニケーション強化 | D6: GV | E6: 質問はコントロール実装状況を問うため、同一コントロールの実装施策と1:1で対応する。 | F6: 現状評価が目標評価未満、または優先度スコアが閾値以上（対象外を除く）
A7: AIMF-GV-ORG-006 | B7: AIMF-GV-ORG-006 | C7: AI統括責任者（CAIO/AIセキュリティ責任者）の任命 | D7: GV | E7: 質問はコントロール実装状況を問うため、同一コントロールの実装施策と1:1で対応する。 | F7: 現状評価が目標評価未満、または優先度スコアが閾値以上（対象外を除く）
A8: AIMF-GV-ORG-007 | B8: AIMF-GV-ORG-007 | C8: AIセキュリティ予算・リソースの確保 | D8: GV | E8: 質問はコントロール実装状況を問うため、同一コントロールの実装施策と1:1で対応する。 | F8: 現状評価が目標評価未満、または優先度スコアが閾値以上（対象外を除く）
A9: AIMF-GV-ORG-008 | B9: AIMF-GV-ORG-008 | C9: AIライフサイクル全体のRACI定義 | D9: GV | E9: 質問はコントロール実装状況を問うため、同一コントロールの実装施策と1:1で対応する。 | F9: 現状評価が目標評価未満、または優先度スコアが閾値以上（対象外を除く）
A10: AIMF-GV-ORG-009 | B10: AIMF-GV-ORG-009 | C10: AI倫理審査との連携プロセス | D10: GV | E10: 質問はコントロール実装状況を問うため、同一コントロールの実装施策と1:1で対応する。 | F10: 現状評価が目標評価未満、または優先度スコアが閾値以上（対象外を除く）
A11: AIMF-GV-POL-001 | B11: AIMF-GV-POL-001 | C11: AIポリシースイートの体系化 | D11: GV | E11: 質問はコントロール実装状況を問うため、同一コントロールの実装施策と1:1で対応する。 | F11: 現状評価が目標評価未満、または優先度スコアが閾値以上（対象外を除く）
A12: AIMF-GV-POL-002 | B12: AIMF-GV-POL-002 | C12: 生成AI利用細則（入力禁止情報・プロンプト取扱規程） | D12: GV | E12: 質問はコントロール実装状況を問うため、同一コントロールの実装施策と1:1で対応する。 | F12: 現状評価が目標評価未満、または優先度スコアが閾値以上（対象外を除く）
... A208: AIMF-RC-PMM-001 | B208: AIMF-RC-PMM-001 | C208: 市販後モニタリング計画（Post-market Monitoring） | D208: RC | E208: 質問はコントロール実装状況を問うため、同一コントロールの実装施策と1:1で対応する。 | F208: 現状評価が目標評価未満、または優先度スコアが閾値以上（対象外を除く）

Sheet 04_依存関係マスター
A1: 施策ID | B1: 施策名 | C1: 依存施策ID | D1: 依存施策名 | E1: 依存理由 | F1: 配置ルール
A2: AIMF-PR-IAM-001 | B2: RAGデータアクセス権（ACL）の同期 | C2: AIMF-ID-AST-002 | D2: RAG知識ベース・データソースの棚卸し | E2: 権限同期の範囲定義に棚卸しが必要 | F2: 棚卸し→ACL同期
A3: AIMF-DE-VUL-001 | B3: SBOM/AI-BOMの継続的脆弱性スキャン | C3: AIMF-ID-SCM-002 | D3: SBOMの自動生成・継続的管理 | E3: スキャン対象のSBOM整備が前提 | F3: SBOM生成→継続スキャン
A4: AIMF-PR-IAM-002 | B4: AIエージェントへの最小権限原則の適用 | C4: AIMF-ID-AST-003 | D4: AIエージェントの権限・ツールトポロジー管理 | E4: 権限の現状把握が最小化設計の前提 | F4: トポロジー把握→最小権限
A5: AIMF-PR-AGT-005 | B5: ツールACLマトリクスによる呼出可否管理 | C5: AIMF-ID-SCM-005 | D5: MCPサーバー・プラグイン・エージェントツールの事前審査 | E5: 承認済みツールリストがACLの前提 | F5: ツール審査→ACL
A6: AIMF-DE-SOC-001 | B6: AIテレメトリのSIEM統合と相関分析 | C6: AIMF-DE-LOG-001 | D6: AIコンポーネント横断のログ標準化 | E6: 相関分析にはログ形式の標準化が必要 | F6: ログ標準化→SIEM統合
A7: AIMF-DE-SOC-004 | B7: AI環境の脅威ハンティング | C7: AIMF-DE-SOC-001 | D7: AIテレメトリのSIEM統合と相関分析 | E7: ハンティングは統合テレメトリが前提 | F7: SIEM統合→ハンティング
A8: AIMF-DE-SOC-002 | B8: ATLAS対応の検知ルールカバレッジ管理 | C8: AIMF-ID-THR-001 | D8: MITRE ATLASに基づくAI脅威モデリング | E8: 対象TTPの特定が先行 | F8: 脅威モデリング→カバレッジ管理
A9: AIMF-PR-GRD-001 | B9: 多層インライン・ガードレール（入出力フィルタ）の実装 | C9: AIMF-ID-AST-001 | D9: AIモデル・サービス管理台帳の整備 | E9: 適用対象システムの可視化が前提 | F9: 台帳→ガードレール
A10: AIMF-DE-AGT-004 | B10: 目標逸脱（ゴールドリフト）の検知 | C10: AIMF-PR-AGT-004 | D10: 最小エージェンシー原則（行動範囲・目標境界の定義） | E10: 承認済み目標の定義が検知基準になる | F10: 目標定義→逸脱検知
A11: AIMF-RS-CON-001 | B11: AIエージェントのキルスイッチ実装 | C11: AIMF-DE-AGT-001 | D11: エージェント状態遷移・思考プロセスの可視化監視 | E11: 停止判断には状態監視が必要 | F11: 状態監視→キルスイッチ
A12: AIMF-PR-MDL-004 | B12: モデルレジストリ統制（承認済みモデルのみデプロイ） | C12: AIMF-ID-SCM-003 | D12: AI-BOMによるAI特有資産の管理 | E12: モデル資産の台帳化が前提 | F12: AI-BOM→レジストリ統制
... A16: AIMF-RS-RPT-001 | B16: インシデントの外部報告・ステークホルダー通知 | C16: AIMF-RS-IRP-004 | D16: AI固有インシデントの分類・重大度基準 | E16: 法定報告該当性の判断基準が前提 | F16: 分類基準→外部報告

Sheet 05_施策抽出
A1: 質問ID | B1: 抽出 | C1: 優先度スコア | D1: ギャップ | E1: 施策ID | F1: 施策名 | G1: 区分
A2: =01_評価入力!A2 -> AIMF-GV-ORG-001 | B2: =01_評価入力!S2 | C2: =01_評価入力!R2 | D2: =01_評価入力!K2 | E2: =01_評価入力!T2 -> AIMF-GV-ORG-001 | F2: =01_評価入力!U2 -> AIガバナンス委員会の設置 | G2: =IF($E2="","",IFERROR(VLOOKUP($E2,02_施策マスター!$A:$C,3,0),"")) -> GV
A3: =01_評価入力!A3 -> AIMF-GV-ORG-002 | B3: =01_評価入力!S3 | C3: =01_評価入力!R3 | D3: =01_評価入力!K3 | E3: =01_評価入力!T3 -> AIMF-GV-ORG-002 | F3: =01_評価入力!U3 -> AI活用基本方針・ガイドラインの策定 | G3: =IF($E3="","",IFERROR(VLOOKUP($E3,02_施策マスター!$A:$C,3,0),"")) -> GV
A4: =01_評価入力!A4 -> AIMF-GV-ORG-003 | B4: =01_評価入力!S4 | C4: =01_評価入力!R4 | D4: =01_評価入力!K4 | E4: =01_評価入力!T4 -> AIMF-GV-ORG-003 | F4: =01_評価入力!U4 -> AIリスクアセスメント・プロジェクト承認プロセスの構築 | G4: =IF($E4="","",IFERROR(VLOOKUP($E4,02_施策マスター!$A:$C,3,0),"")) -> GV
A5: =01_評価入力!A5 -> AIMF-GV-ORG-004 | B5: =01_評価入力!S5 | C5: =01_評価入力!R5 | D5: =01_評価入力!K5 | E5: =01_評価入力!T5 -> AIMF-GV-ORG-004 | F5: =01_評価入力!U5 -> AIセキュリティ文化の醸成 | G5: =IF($E5="","",IFERROR(VLOOKUP($E5,02_施策マスター!$A:$C,3,0),"")) -> GV
A6: =01_評価入力!A6 -> AIMF-GV-ORG-005 | B6: =01_評価入力!S6 | C6: =01_評価入力!R6 | D6: =01_評価入力!K6 | E6: =01_評価入力!T6 -> AIMF-GV-ORG-005 | F6: =01_評価入力!U6 -> AIセキュリティの社内コミュニケーション強化 | G6: =IF($E6="","",IFERROR(VLOOKUP($E6,02_施策マスター!$A:$C,3,0),"")) -> GV
A7: =01_評価入力!A7 -> AIMF-GV-ORG-006 | B7: =01_評価入力!S7 | C7: =01_評価入力!R7 | D7: =01_評価入力!K7 | E7: =01_評価入力!T7 -> AIMF-GV-ORG-006 | F7: =01_評価入力!U7 -> AI統括責任者（CAIO/AIセキュリティ責任者）の任命 | G7: =IF($E7="","",IFERROR(VLOOKUP($E7,02_施策マスター!$A:$C,3,0),"")) -> GV
A8: =01_評価入力!A8 -> AIMF-GV-ORG-007 | B8: =01_評価入力!S8 | C8: =01_評価入力!R8 | D8: =01_評価入力!K8 | E8: =01_評価入力!T8 -> AIMF-GV-ORG-007 | F8: =01_評価入力!U8 -> AIセキュリティ予算・リソースの確保 | G8: =IF($E8="","",IFERROR(VLOOKUP($E8,02_施策マスター!$A:$C,3,0),"")) -> GV
A9: =01_評価入力!A9 -> AIMF-GV-ORG-008 | B9: =01_評価入力!S9 | C9: =01_評価入力!R9 | D9: =01_評価入力!K9 | E9: =01_評価入力!T9 -> AIMF-GV-ORG-008 | F9: =01_評価入力!U9 -> AIライフサイクル全体のRACI定義 | G9: =IF($E9="","",IFERROR(VLOOKUP($E9,02_施策マスター!$A:$C,3,0),"")) -> GV
A10: =01_評価入力!A10 -> AIMF-GV-ORG-009 | B10: =01_評価入力!S10 | C10: =01_評価入力!R10 | D10: =01_評価入力!K10 | E10: =01_評価入力!T10 -> AIMF-GV-ORG-009 | F10: =01_評価入力!U10 -> AI倫理審査との連携プロセス | G10: =IF($E10="","",IFERROR(VLOOKUP($E10,02_施策マスター!$A:$C,3,0),"")) -> GV
A11: =01_評価入力!A11 -> AIMF-GV-POL-001 | B11: =01_評価入力!S11 | C11: =01_評価入力!R11 | D11: =01_評価入力!K11 | E11: =01_評価入力!T11 -> AIMF-GV-POL-001 | F11: =01_評価入力!U11 -> AIポリシースイートの体系化 | G11: =IF($E11="","",IFERROR(VLOOKUP($E11,02_施策マスター!$A:$C,3,0),"")) -> GV
A12: =01_評価入力!A12 -> AIMF-GV-POL-002 | B12: =01_評価入力!S12 | C12: =01_評価入力!R12 | D12: =01_評価入力!K12 | E12: =01_評価入力!T12 -> AIMF-GV-POL-002 | F12: =01_評価入力!U12 -> 生成AI利用細則（入力禁止情報・プロンプト取扱規程） | G12: =IF($E12="","",IFERROR(VLOOKUP($E12,02_施策マスター!$A:$C,3,0),"")) -> GV
A13: =01_評価入力!A13 -> AIMF-GV-POL-003 | B13: =01_評価入力!S13 | C13: =01_評価入力!R13 | D13: =01_評価入力!K13 | E13: =01_評価入力!T13 -> AIMF-GV-POL-003 | F13: =01_評価入力!U13 -> 承認済みAIサービスカタログと例外管理 | G13: =IF($E13="","",IFERROR(VLOOKUP($E13,02_施策マスター!$A:$C,3,0),"")) -> GV
... A208: =01_評価入力!A208 -> AIMF-RC-PMM-001 | B208: =01_評価入力!S208 | C208: =01_評価入力!R208 | D208: =01_評価入力!K208 | E208: =01_評価入力!T208 -> AIMF-RC-PMM-001 | F208: =01_評価入力!U208 -> 市販後モニタリング計画（Post-market Monitoring） | G208: =IF($E208="","",IFERROR(VLOOKUP($E208,02_施策マスター!$A:$C,3,0),"")) -> RC

Sheet 06_重複排除後
A1: 施策ID | B1: 施策名 | C1: 区分 | D1: ロードマップ区分 | E1: 標準期間(月) | F1: 導入難易度 | G1: 抽出回数 | H1: 採用 | I1: 推奨優先度 | J1: 調整優先度(内部) | K1: 区分内順位(内部) | L1: 順位キー(内部)
A2: =02_施策マスター!A2 -> AIMF-GV-ORG-001 | B2: =02_施策マスター!B2 -> AIガバナンス委員会の設置 | C2: =02_施策マスター!C2 -> GV | D2: =02_施策マスター!O2 -> 短期 | E2: =02_施策マスター!I2 -> 3 | F2: =02_施策マスター!H2 -> 2 | G2: =COUNTIFS(05_施策抽出!$E:$E,$A2,05_施策抽出!$B:$B,"○") -> 0 | H2: =IF($G2>0,"○","") | I2: =IF($H2="","",ROUND(SUMIFS(05_施策抽出!$C:$C,05_施策抽出!$E:$E,$A2,05_施策抽出!$B:$B,"○")*02_施策マスター!$P2*02_施策マスター!$K2,1)) | J2: =IF($I2="","",$I2+(1000-ROW())/1000000) | K2: =IF($H2="","",COUNTIFS($D$2:$D$208,$D2,$J$2:$J$208,">"&$J2)+1) | L2: =IF($K2="","",$D2&"-"&$K2)
A3: =02_施策マスター!A3 -> AIMF-GV-ORG-002 | B3: =02_施策マスター!B3 -> AI活用基本方針・ガイドラインの策定 | C3: =02_施策マスター!C3 -> GV | D3: =02_施策マスター!O3 -> 短期 | E3: =02_施策マスター!I3 -> 3 | F3: =02_施策マスター!H3 -> 2 | G3: =COUNTIFS(05_施策抽出!$E:$E,$A3,05_施策抽出!$B:$B,"○") -> 0 | H3: =IF($G3>0,"○","") | I3: =IF($H3="","",ROUND(SUMIFS(05_施策抽出!$C:$C,05_施策抽出!$E:$E,$A3,05_施策抽出!$B:$B,"○")*02_施策マスター!$P3*02_施策マスター!$K3,1)) | J3: =IF($I3="","",$I3+(1000-ROW())/1000000) | K3: =IF($H3="","",COUNTIFS($D$2:$D$208,$D3,$J$2:$J$208,">"&$J3)+1) | L3: =IF($K3="","",$D3&"-"&$K3)
A4: =02_施策マスター!A4 -> AIMF-GV-ORG-003 | B4: =02_施策マスター!B4 -> AIリスクアセスメント・プロジェクト承認プロセスの構築 | C4: =02_施策マスター!C4 -> GV | D4: =02_施策マスター!O4 -> 短期 | E4: =02_施策マスター!I4 -> 3 | F4: =02_施策マスター!H4 -> 2 | G4: =COUNTIFS(05_施策抽出!$E:$E,$A4,05_施策抽出!$B:$B,"○") -> 0 | H4: =IF($G4>0,"○","") | I4: =IF($H4="","",ROUND(SUMIFS(05_施策抽出!$C:$C,05_施策抽出!$E:$E,$A4,05_施策抽出!$B:$B,"○")*02_施策マスター!$P4*02_施策マスター!$K4,1)) | J4: =IF($I4="","",$I4+(1000-ROW())/1000000) | K4: =IF($H4="","",COUNTIFS($D$2:$D$208,$D4,$J$2:$J$208,">"&$J4)+1) | L4: =IF($K4="","",$D4&"-"&$K4)
A5: =02_施策マスター!A5 -> AIMF-GV-ORG-004 | B5: =02_施策マスター!B5 -> AIセキュリティ文化の醸成 | C5: =02_施策マスター!C5 -> GV | D5: =02_施策マスター!O5 -> 短期 | E5: =02_施策マスター!I5 -> 3 | F5: =02_施策マスター!H5 -> 2 | G5: =COUNTIFS(05_施策抽出!$E:$E,$A5,05_施策抽出!$B:$B,"○") -> 0 | H5: =IF($G5>0,"○","") | I5: =IF($H5="","",ROUND(SUMIFS(05_施策抽出!$C:$C,05_施策抽出!$E:$E,$A5,05_施策抽出!$B:$B,"○")*02_施策マスター!$P5*02_施策マスター!$K5,1)) | J5: =IF($I5="","",$I5+(1000-ROW())/1000000) | K5: =IF($H5="","",COUNTIFS($D$2:$D$208,$D5,$J$2:$J$208,">"&$J5)+1) | L5: =IF($K5="","",$D5&"-"&$K5)
A6: =02_施策マスター!A6 -> AIMF-GV-ORG-005 | B6: =02_施策マスター!B6 -> AIセキュリティの社内コミュニケーション強化 | C6: =02_施策マスター!C6 -> GV | D6: =02_施策マスター!O6 -> 短期 | E6: =02_施策マスター!I6 -> 3 | F6: =02_施策マスター!H6 -> 2 | G6: =COUNTIFS(05_施策抽出!$E:$E,$A6,05_施策抽出!$B:$B,"○") -> 0 | H6: =IF($G6>0,"○","") | I6: =IF($H6="","",ROUND(SUMIFS(05_施策抽出!$C:$C,05_施策抽出!$E:$E,$A6,05_施策抽出!$B:$B,"○")*02_施策マスター!$P6*02_施策マスター!$K6,1)) | J6: =IF($I6="","",$I6+(1000-ROW())/1000000) | K6: =IF($H6="","",COUNTIFS($D$2:$D$208,$D6,$J$2:$J$208,">"&$J6)+1) | L6: =IF($K6="","",$D6&"-"&$K6)
A7: =02_施策マスター!A7 -> AIMF-GV-ORG-006 | B7: =02_施策マスター!B7 -> AI統括責任者（CAIO/AIセキュリティ責任者）の任命 | C7: =02_施策マスター!C7 -> GV | D7: =02_施策マスター!O7 -> 短期 | E7: =02_施策マスター!I7 -> 3 | F7: =02_施策マスター!H7 -> 2 | G7: =COUNTIFS(05_施策抽出!$E:$E,$A7,05_施策抽出!$B:$B,"○") -> 0 | H7: =IF($G7>0,"○","") | I7: =IF($H7="","",ROUND(SUMIFS(05_施策抽出!$C:$C,05_施策抽出!$E:$E,$A7,05_施策抽出!$B:$B,"○")*02_施策マスター!$P7*02_施策マスター!$K7,1)) | J7: =IF($I7="","",$I7+(1000-ROW())/1000000) | K7: =IF($H7="","",COUNTIFS($D$2:$D$208,$D7,$J$2:$J$208,">"&$J7)+1) | L7: =IF($K7="","",$D7&"-"&$K7)
A8: =02_施策マスター!A8 -> AIMF-GV-ORG-007 | B8: =02_施策マスター!B8 -> AIセキュリティ予算・リソースの確保 | C8: =02_施策マスター!C8 -> GV | D8: =02_施策マスター!O8 -> 短期 | E8: =02_施策マスター!I8 -> 3 | F8: =02_施策マスター!H8 -> 2 | G8: =COUNTIFS(05_施策抽出!$E:$E,$A8,05_施策抽出!$B:$B,"○") -> 0 | H8: =IF($G8>0,"○","") | I8: =IF($H8="","",ROUND(SUMIFS(05_施策抽出!$C:$C,05_施策抽出!$E:$E,$A8,05_施策抽出!$B:$B,"○")*02_施策マスター!$P8*02_施策マスター!$K8,1)) | J8: =IF($I8="","",$I8+(1000-ROW())/1000000) | K8: =IF($H8="","",COUNTIFS($D$2:$D$208,$D8,$J$2:$J$208,">"&$J8)+1) | L8: =IF($K8="","",$D8&"-"&$K8)
A9: =02_施策マスター!A9 -> AIMF-GV-ORG-008 | B9: =02_施策マスター!B9 -> AIライフサイクル全体のRACI定義 | C9: =02_施策マスター!C9 -> GV | D9: =02_施策マスター!O9 -> 短期 | E9: =02_施策マスター!I9 -> 3 | F9: =02_施策マスター!H9 -> 2 | G9: =COUNTIFS(05_施策抽出!$E:$E,$A9,05_施策抽出!$B:$B,"○") -> 0 | H9: =IF($G9>0,"○","") | I9: =IF($H9="","",ROUND(SUMIFS(05_施策抽出!$C:$C,05_施策抽出!$E:$E,$A9,05_施策抽出!$B:$B,"○")*02_施策マスター!$P9*02_施策マスター!$K9,1)) | J9: =IF($I9="","",$I9+(1000-ROW())/1000000) | K9: =IF($H9="","",COUNTIFS($D$2:$D$208,$D9,$J$2:$J$208,">"&$J9)+1) | L9: =IF($K9="","",$D9&"-"&$K9)
A10: =02_施策マスター!A10 -> AIMF-GV-ORG-009 | B10: =02_施策マスター!B10 -> AI倫理審査との連携プロセス | C10: =02_施策マスター!C10 -> GV | D10: =02_施策マスター!O10 -> 短期 | E10: =02_施策マスター!I10 -> 3 | F10: =02_施策マスター!H10 -> 2 | G10: =COUNTIFS(05_施策抽出!$E:$E,$A10,05_施策抽出!$B:$B,"○") -> 0 | H10: =IF($G10>0,"○","") | I10: =IF($H10="","",ROUND(SUMIFS(05_施策抽出!$C:$C,05_施策抽出!$E:$E,$A10,05_施策抽出!$B:$B,"○")*02_施策マスター!$P10*02_施策マスター!$K10,1)) | J10: =IF($I10="","",$I10+(1000-ROW())/1000000) | K10: =IF($H10="","",COUNTIFS($D$2:$D$208,$D10,$J$2:$J$208,">"&$J10)+1) | L10: =IF($K10="","",$D10&"-"&$K10)
A11: =02_施策マスター!A11 -> AIMF-GV-POL-001 | B11: =02_施策マスター!B11 -> AIポリシースイートの体系化 | C11: =02_施策マスター!C11 -> GV | D11: =02_施策マスター!O11 -> 短期 | E11: =02_施策マスター!I11 -> 3 | F11: =02_施策マスター!H11 -> 2 | G11: =COUNTIFS(05_施策抽出!$E:$E,$A11,05_施策抽出!$B:$B,"○") -> 0 | H11: =IF($G11>0,"○","") | I11: =IF($H11="","",ROUND(SUMIFS(05_施策抽出!$C:$C,05_施策抽出!$E:$E,$A11,05_施策抽出!$B:$B,"○")*02_施策マスター!$P11*02_施策マスター!$K11,1)) | J11: =IF($I11="","",$I11+(1000-ROW())/1000000) | K11: =IF($H11="","",COUNTIFS($D$2:$D$208,$D11,$J$2:$J$208,">"&$J11)+1) | L11: =IF($K11="","",$D11&"-"&$K11)
A12: =02_施策マスター!A12 -> AIMF-GV-POL-002 | B12: =02_施策マスター!B12 -> 生成AI利用細則（入力禁止情報・プロンプト取扱規程） | C12: =02_施策マスター!C12 -> GV | D12: =02_施策マスター!O12 -> 中期 | E12: =02_施策マスター!I12 -> 6 | F12: =02_施策マスター!H12 -> 3 | G12: =COUNTIFS(05_施策抽出!$E:$E,$A12,05_施策抽出!$B:$B,"○") -> 0 | H12: =IF($G12>0,"○","") | I12: =IF($H12="","",ROUND(SUMIFS(05_施策抽出!$C:$C,05_施策抽出!$E:$E,$A12,05_施策抽出!$B:$B,"○")*02_施策マスター!$P12*02_施策マスター!$K12,1)) | J12: =IF($I12="","",$I12+(1000-ROW())/1000000) | K12: =IF($H12="","",COUNTIFS($D$2:$D$208,$D12,$J$2:$J$208,">"&$J12)+1) | L12: =IF($K12="","",$D12&"-"&$K12)
A13: =02_施策マスター!A13 -> AIMF-GV-POL-003 | B13: =02_施策マスター!B13 -> 承認済みAIサービスカタログと例外管理 | C13: =02_施策マスター!C13 -> GV | D13: =02_施策マスター!O13 -> 短期 | E13: =02_施策マスター!I13 -> 3 | F13: =02_施策マスター!H13 -> 2 | G13: =COUNTIFS(05_施策抽出!$E:$E,$A13,05_施策抽出!$B:$B,"○") -> 0 | H13: =IF($G13>0,"○","") | I13: =IF($H13="","",ROUND(SUMIFS(05_施策抽出!$C:$C,05_施策抽出!$E:$E,$A13,05_施策抽出!$B:$B,"○")*02_施策マスター!$P13*02_施策マスター!$K13,1)) | J13: =IF($I13="","",$I13+(1000-ROW())/1000000) | K13: =IF($H13="","",COUNTIFS($D$2:$D$208,$D13,$J$2:$J$208,">"&$J13)+1) | L13: =IF($K13="","",$D13&"-"&$K13)
... A208: =02_施策マスター!A208 -> AIMF-RC-PMM-001 | B208: =02_施策マスター!B208 -> 市販後モニタリング計画（Post-market Monitoring） | C208: =02_施策マスター!C208 -> RC | D208: =02_施策マスター!O208 -> 中期 | E208: =02_施策マスター!I208 -> 6 | F208: =02_施策マスター!H208 -> 3 | G208: =COUNTIFS(05_施策抽出!$E:$E,$A208,05_施策抽出!$B:$B,"○") -> 0 | H208: =IF($G208>0,"○","") | I208: =IF($H208="","",ROUND(SUMIFS(05_施策抽出!$C:$C,05_施策抽出!$E:$E,$A208,05_施策抽出!$B:$B,"○")*02_施策マスター!$P208*02_施策マスター!$K208,1)) | J208: =IF($I208="","",$I208+(1000-ROW())/1000000) | K208: =IF($H208="","",COUNTIFS($D$2:$D$208,$D208,$J$2:$J$208,">"&$J208)+1) | L208: =IF($K208="","",$D208&"-"&$K208)

Sheet 07_短中長Top5
A1: 短期 Top5（〜6か月） | F1: 中期 Top5（6〜18か月） | K1: 長期 Top5（18か月〜）
A2: 順位 | B2: 施策ID | C2: 施策名 | D2: 推奨優先度 | F2: 順位 | G2: 施策ID | H2: 施策名 | I2: 推奨優先度 | K2: 順位 | L2: 施策ID | M2: 施策名 | N2: 推奨優先度
A3: 1 | B3: =IFERROR(INDEX(06_重複排除後!$A:$A,MATCH("短期-"&$A3,06_重複排除後!$L:$L,0)),"") | C3: =IF($B3="","",VLOOKUP($B3,06_重複排除後!$A:$B,2,0)) | D3: =IF($B3="","",VLOOKUP($B3,06_重複排除後!$A:$I,9,0)) | F3: 1 | G3: =IFERROR(INDEX(06_重複排除後!$A:$A,MATCH("中期-"&$F3,06_重複排除後!$L:$L,0)),"") | H3: =IF($G3="","",VLOOKUP($G3,06_重複排除後!$A:$B,2,0)) | I3: =IF($G3="","",VLOOKUP($G3,06_重複排除後!$A:$I,9,0)) | K3: 1 | L3: =IFERROR(INDEX(06_重複排除後!$A:$A,MATCH("長期-"&$K3,06_重複排除後!$L:$L,0)),"") | M3: =IF($L3="","",VLOOKUP($L3,06_重複排除後!$A:$B,2,0)) | N3: =IF($L3="","",VLOOKUP($L3,06_重複排除後!$A:$I,9,0))
A4: 2 | B4: =IFERROR(INDEX(06_重複排除後!$A:$A,MATCH("短期-"&$A4,06_重複排除後!$L:$L,0)),"") | C4: =IF($B4="","",VLOOKUP($B4,06_重複排除後!$A:$B,2,0)) | D4: =IF($B4="","",VLOOKUP($B4,06_重複排除後!$A:$I,9,0)) | F4: 2 | G4: =IFERROR(INDEX(06_重複排除後!$A:$A,MATCH("中期-"&$F4,06_重複排除後!$L:$L,0)),"") | H4: =IF($G4="","",VLOOKUP($G4,06_重複排除後!$A:$B,2,0)) | I4: =IF($G4="","",VLOOKUP($G4,06_重複排除後!$A:$I,9,0)) | K4: 2 | L4: =IFERROR(INDEX(06_重複排除後!$A:$A,MATCH("長期-"&$K4,06_重複排除後!$L:$L,0)),"") | M4: =IF($L4="","",VLOOKUP($L4,06_重複排除後!$A:$B,2,0)) | N4: =IF($L4="","",VLOOKUP($L4,06_重複排除後!$A:$I,9,0))
A5: 3 | B5: =IFERROR(INDEX(06_重複排除後!$A:$A,MATCH("短期-"&$A5,06_重複排除後!$L:$L,0)),"") | C5: =IF($B5="","",VLOOKUP($B5,06_重複排除後!$A:$B,2,0)) | D5: =IF($B5="","",VLOOKUP($B5,06_重複排除後!$A:$I,9,0)) | F5: 3 | G5: =IFERROR(INDEX(06_重複排除後!$A:$A,MATCH("中期-"&$F5,06_重複排除後!$L:$L,0)),"") | H5: =IF($G5="","",VLOOKUP($G5,06_重複排除後!$A:$B,2,0)) | I5: =IF($G5="","",VLOOKUP($G5,06_重複排除後!$A:$I,9,0)) | K5: 3 | L5: =IFERROR(INDEX(06_重複排除後!$A:$A,MATCH("長期-"&$K5,06_重複排除後!$L:$L,0)),"") | M5: =IF($L5="","",VLOOKUP($L5,06_重複排除後!$A:$B,2,0)) | N5: =IF($L5="","",VLOOKUP($L5,06_重複排除後!$A:$I,9,0))
A6: 4 | B6: =IFERROR(INDEX(06_重複排除後!$A:$A,MATCH("短期-"&$A6,06_重複排除後!$L:$L,0)),"") | C6: =IF($B6="","",VLOOKUP($B6,06_重複排除後!$A:$B,2,0)) | D6: =IF($B6="","",VLOOKUP($B6,06_重複排除後!$A:$I,9,0)) | F6: 4 | G6: =IFERROR(INDEX(06_重複排除後!$A:$A,MATCH("中期-"&$F6,06_重複排除後!$L:$L,0)),"") | H6: =IF($G6="","",VLOOKUP($G6,06_重複排除後!$A:$B,2,0)) | I6: =IF($G6="","",VLOOKUP($G6,06_重複排除後!$A:$I,9,0)) | K6: 4 | L6: =IFERROR(INDEX(06_重複排除後!$A:$A,MATCH("長期-"&$K6,06_重複排除後!$L:$L,0)),"") | M6: =IF($L6="","",VLOOKUP($L6,06_重複排除後!$A:$B,2,0)) | N6: =IF($L6="","",VLOOKUP($L6,06_重複排除後!$A:$I,9,0))
A7: 5 | B7: =IFERROR(INDEX(06_重複排除後!$A:$A,MATCH("短期-"&$A7,06_重複排除後!$L:$L,0)),"") | C7: =IF($B7="","",VLOOKUP($B7,06_重複排除後!$A:$B,2,0)) | D7: =IF($B7="","",VLOOKUP($B7,06_重複排除後!$A:$I,9,0)) | F7: 5 | G7: =IFERROR(INDEX(06_重複排除後!$A:$A,MATCH("中期-"&$F7,06_重複排除後!$L:$L,0)),"") | H7: =IF($G7="","",VLOOKUP($G7,06_重複排除後!$A:$B,2,0)) | I7: =IF($G7="","",VLOOKUP($G7,06_重複排除後!$A:$I,9,0)) | K7: 5 | L7: =IFERROR(INDEX(06_重複排除後!$A:$A,MATCH("長期-"&$K7,06_重複排除後!$L:$L,0)),"") | M7: =IF($L7="","",VLOOKUP($L7,06_重複排除後!$A:$B,2,0)) | N7: =IF($L7="","",VLOOKUP($L7,06_重複排除後!$A:$I,9,0))

Sheet 08_ロードマップ
A1: 区分 | B1: 順位 | C1: 施策ID | D1: 施策名 | E1: AIMF区分 | F1: 標準期間(月) | G1: 推奨優先度 | H1: (内部)区分 | I1: (内部)順位
A2: =IF($C2="","",$H2) | B2: =IF($C2="","",$I2) | C2: =IFERROR(INDEX(06_重複排除後!$A:$A,MATCH($H2&"-"&$I2,06_重複排除後!$L:$L,0)),"") | D2: =IF($C2="","",VLOOKUP($C2,06_重複排除後!$A:$B,2,0)) | E2: =IF($C2="","",VLOOKUP($C2,06_重複排除後!$A:$C,3,0)) | F2: =IF($C2="","",VLOOKUP($C2,06_重複排除後!$A:$E,5,0)) | G2: =IF($C2="","",VLOOKUP($C2,06_重複排除後!$A:$I,9,0)) | H2: 短期 | I2: 1
A3: =IF($C3="","",$H3) | B3: =IF($C3="","",$I3) | C3: =IFERROR(INDEX(06_重複排除後!$A:$A,MATCH($H3&"-"&$I3,06_重複排除後!$L:$L,0)),"") | D3: =IF($C3="","",VLOOKUP($C3,06_重複排除後!$A:$B,2,0)) | E3: =IF($C3="","",VLOOKUP($C3,06_重複排除後!$A:$C,3,0)) | F3: =IF($C3="","",VLOOKUP($C3,06_重複排除後!$A:$E,5,0)) | G3: =IF($C3="","",VLOOKUP($C3,06_重複排除後!$A:$I,9,0)) | H3: 短期 | I3: 2
A4: =IF($C4="","",$H4) | B4: =IF($C4="","",$I4) | C4: =IFERROR(INDEX(06_重複排除後!$A:$A,MATCH($H4&"-"&$I4,06_重複排除後!$L:$L,0)),"") | D4: =IF($C4="","",VLOOKUP($C4,06_重複排除後!$A:$B,2,0)) | E4: =IF($C4="","",VLOOKUP($C4,06_重複排除後!$A:$C,3,0)) | F4: =IF($C4="","",VLOOKUP($C4,06_重複排除後!$A:$E,5,0)) | G4: =IF($C4="","",VLOOKUP($C4,06_重複排除後!$A:$I,9,0)) | H4: 短期 | I4: 3
A5: =IF($C5="","",$H5) | B5: =IF($C5="","",$I5) | C5: =IFERROR(INDEX(06_重複排除後!$A:$A,MATCH($H5&"-"&$I5,06_重複排除後!$L:$L,0)),"") | D5: =IF($C5="","",VLOOKUP($C5,06_重複排除後!$A:$B,2,0)) | E5: =IF($C5="","",VLOOKUP($C5,06_重複排除後!$A:$C,3,0)) | F5: =IF($C5="","",VLOOKUP($C5,06_重複排除後!$A:$E,5,0)) | G5: =IF($C5="","",VLOOKUP($C5,06_重複排除後!$A:$I,9,0)) | H5: 短期 | I5: 4
A6: =IF($C6="","",$H6) | B6: =IF($C6="","",$I6) | C6: =IFERROR(INDEX(06_重複排除後!$A:$A,MATCH($H6&"-"&$I6,06_重複排除後!$L:$L,0)),"") | D6: =IF($C6="","",VLOOKUP($C6,06_重複排除後!$A:$B,2,0)) | E6: =IF($C6="","",VLOOKUP($C6,06_重複排除後!$A:$C,3,0)) | F6: =IF($C6="","",VLOOKUP($C6,06_重複排除後!$A:$E,5,0)) | G6: =IF($C6="","",VLOOKUP($C6,06_重複排除後!$A:$I,9,0)) | H6: 短期 | I6: 5
A7: =IF($C7="","",$H7) | B7: =IF($C7="","",$I7) | C7: =IFERROR(INDEX(06_重複排除後!$A:$A,MATCH($H7&"-"&$I7,06_重複排除後!$L:$L,0)),"") | D7: =IF($C7="","",VLOOKUP($C7,06_重複排除後!$A:$B,2,0)) | E7: =IF($C7="","",VLOOKUP($C7,06_重複排除後!$A:$C,3,0)) | F7: =IF($C7="","",VLOOKUP($C7,06_重複排除後!$A:$E,5,0)) | G7: =IF($C7="","",VLOOKUP($C7,06_重複排除後!$A:$I,9,0)) | H7: 短期 | I7: 6
A8: =IF($C8="","",$H8) | B8: =IF($C8="","",$I8) | C8: =IFERROR(INDEX(06_重複排除後!$A:$A,MATCH($H8&"-"&$I8,06_重複排除後!$L:$L,0)),"") | D8: =IF($C8="","",VLOOKUP($C8,06_重複排除後!$A:$B,2,0)) | E8: =IF($C8="","",VLOOKUP($C8,06_重複排除後!$A:$C,3,0)) | F8: =IF($C8="","",VLOOKUP($C8,06_重複排除後!$A:$E,5,0)) | G8: =IF($C8="","",VLOOKUP($C8,06_重複排除後!$A:$I,9,0)) | H8: 短期 | I8: 7
A9: =IF($C9="","",$H9) | B9: =IF($C9="","",$I9) | C9: =IFERROR(INDEX(06_重複排除後!$A:$A,MATCH($H9&"-"&$I9,06_重複排除後!$L:$L,0)),"") | D9: =IF($C9="","",VLOOKUP($C9,06_重複排除後!$A:$B,2,0)) | E9: =IF($C9="","",VLOOKUP($C9,06_重複排除後!$A:$C,3,0)) | F9: =IF($C9="","",VLOOKUP($C9,06_重複排除後!$A:$E,5,0)) | G9: =IF($C9="","",VLOOKUP($C9,06_重複排除後!$A:$I,9,0)) | H9: 短期 | I9: 8
A10: =IF($C10="","",$H10) | B10: =IF($C10="","",$I10) | C10: =IFERROR(INDEX(06_重複排除後!$A:$A,MATCH($H10&"-"&$I10,06_重複排除後!$L:$L,0)),"") | D10: =IF($C10="","",VLOOKUP($C10,06_重複排除後!$A:$B,2,0)) | E10: =IF($C10="","",VLOOKUP($C10,06_重複排除後!$A:$C,3,0)) | F10: =IF($C10="","",VLOOKUP($C10,06_重複排除後!$A:$E,5,0)) | G10: =IF($C10="","",VLOOKUP($C10,06_重複排除後!$A:$I,9,0)) | H10: 短期 | I10: 9
A11: =IF($C11="","",$H11) | B11: =IF($C11="","",$I11) | C11: =IFERROR(INDEX(06_重複排除後!$A:$A,MATCH($H11&"-"&$I11,06_重複排除後!$L:$L,0)),"") | D11: =IF($C11="","",VLOOKUP($C11,06_重複排除後!$A:$B,2,0)) | E11: =IF($C11="","",VLOOKUP($C11,06_重複排除後!$A:$C,3,0)) | F11: =IF($C11="","",VLOOKUP($C11,06_重複排除後!$A:$E,5,0)) | G11: =IF($C11="","",VLOOKUP($C11,06_重複排除後!$A:$I,9,0)) | H11: 短期 | I11: 10
A12: =IF($C12="","",$H12) | B12: =IF($C12="","",$I12) | C12: =IFERROR(INDEX(06_重複排除後!$A:$A,MATCH($H12&"-"&$I12,06_重複排除後!$L:$L,0)),"") | D12: =IF($C12="","",VLOOKUP($C12,06_重複排除後!$A:$B,2,0)) | E12: =IF($C12="","",VLOOKUP($C12,06_重複排除後!$A:$C,3,0)) | F12: =IF($C12="","",VLOOKUP($C12,06_重複排除後!$A:$E,5,0)) | G12: =IF($C12="","",VLOOKUP($C12,06_重複排除後!$A:$I,9,0)) | H12: 短期 | I12: 11
A13: =IF($C13="","",$H13) | B13: =IF($C13="","",$I13) | C13: =IFERROR(INDEX(06_重複排除後!$A:$A,MATCH($H13&"-"&$I13,06_重複排除後!$L:$L,0)),"") | D13: =IF($C13="","",VLOOKUP($C13,06_重複排除後!$A:$B,2,0)) | E13: =IF($C13="","",VLOOKUP($C13,06_重複排除後!$A:$C,3,0)) | F13: =IF($C13="","",VLOOKUP($C13,06_重複排除後!$A:$E,5,0)) | G13: =IF($C13="","",VLOOKUP($C13,06_重複排除後!$A:$I,9,0)) | H13: 短期 | I13: 12
... A208: =IF($C208="","",$H208) | B208: =IF($C208="","",$I208) | C208: =IFERROR(INDEX(06_重複排除後!$A:$A,MATCH($H208&"-"&$I208,06_重複排除後!$L:$L,0)),"") | D208: =IF($C208="","",VLOOKUP($C208,06_重複排除後!$A:$B,2,0)) | E208: =IF($C208="","",VLOOKUP($C208,06_重複排除後!$A:$C,3,0)) | F208: =IF($C208="","",VLOOKUP($C208,06_重複排除後!$A:$E,5,0)) | G208: =IF($C208="","",VLOOKUP($C208,06_重複排除後!$A:$I,9,0)) | H208: 長期 | I208: 87

Sheet 09_ガント元データ
A1: 施策ID | B1: 施策名 | C1: 区分 | D1: 標準期間(月) | E1: 依存施策ID | F1: 依存採用 | G1: 開始月 | H1: 終了月
A2: =08_ロードマップ!C2 | B2: =IF($A2="","",08_ロードマップ!D2) | C2: =IF($A2="","",08_ロードマップ!A2) | D2: =IF($A2="","",08_ロードマップ!F2) | E2: =IF($A2="","",IFERROR(VLOOKUP($A2,04_依存関係マスター!$A:$C,3,0),"")) | F2: =IF($E2="","",IF(COUNTIFS(06_重複排除後!$A:$A,$E2,06_重複排除後!$H:$H,"○")>0,"採用","")) | G2: =IF($A2="","",MAX(IF($C2="短期",00_はじめに!$B$20,IF($C2="中期",00_はじめに!$B$21,00_はじめに!$B$22)),IF($F2="採用",IFERROR(VLOOKUP($E2,$A:$H,8,0)+1,0),0))) | H2: =IF($A2="","",MIN(36,$G2+$D2-1))
A3: =08_ロードマップ!C3 | B3: =IF($A3="","",08_ロードマップ!D3) | C3: =IF($A3="","",08_ロードマップ!A3) | D3: =IF($A3="","",08_ロードマップ!F3) | E3: =IF($A3="","",IFERROR(VLOOKUP($A3,04_依存関係マスター!$A:$C,3,0),"")) | F3: =IF($E3="","",IF(COUNTIFS(06_重複排除後!$A:$A,$E3,06_重複排除後!$H:$H,"○")>0,"採用","")) | G3: =IF($A3="","",MAX(IF($C3="短期",00_はじめに!$B$20,IF($C3="中期",00_はじめに!$B$21,00_はじめに!$B$22)),IF($F3="採用",IFERROR(VLOOKUP($E3,$A:$H,8,0)+1,0),0))) | H3: =IF($A3="","",MIN(36,$G3+$D3-1))
